Workbook

Sheet New Orders CRs
A1: Employee Name | C1: Current WorkLoad (InProgress) | D1: Not Started | E1: Dataset Validation | F1: Actual Mapping | G1: Testing | H1: Ready For Production | I1: Latest Assignment Date | K1: Forms | L1: Forms Mapping | M1: Forms Testing | N1: Forms Migration Testing (Ready for Production) | O1: Forms Production | P1: Latest Assignment Date | Q1: Total Queue / Analyst | R1: Total CRs (2025) | S1: Total CRs (2026)
A2: Expected Queue | C2: 20
A3: Ahmed Ali | C3: =SUM(D3:G3) -> 25 | D3: =COUNTIFS([1]EDI!$S$2:$S$10000,"Ahmed Ali", [1]EDI!$Q$2:$Q$10000, "In Progress", [1]EDI!$N$2:$N$10000,"DataSet Validation", [1]EDI!$L$2:$L$10000,"", [1]EDI!$I$2:$I$10000,"EDI") -> 0 | E3: =COUNTIFS([1]EDI!$S$2:$S$10000,"Ahmed Ali", [1]EDI!$Q$2:$Q$10000, "In Progress", [1]EDI!$N$2:$N$10000,"Dataset Validation", [1]EDI!$L$2:$L$10000, "<>", [1]EDI!$I$2:$I$10000,"EDI") -> 1 | F3: =COUNTIFS([1]EDI!$S$2:$S$10000,"Ahmed Ali", [1]EDI!$Q$2:$Q$10000, "In Progress", [1]EDI!$N$2:$N$10000,"Mapping", [1]EDI!$I$2:$I$10000,"EDI") -> 5 | G3: =COUNTIFS([1]EDI!$S$2:$S$10000,"Ahmed Ali", [1]EDI!$Q$2:$Q$10000, "In Progress", [1]EDI!$N$2:$N$10000,"Testing", [1]EDI!$I$2:$I$10000,"EDI") -> 19 | H3: =COUNTIFS([1]EDI!$S$2:$S$10000,"Ahmed Ali", [1]EDI!$Q$2:$Q$10000, "In Progress", [1]EDI!$N$2:$N$10000,"Ready For Production", [1]EDI!$I$2:$I$10000,"EDI") -> 0 | I3: =LARGE(Dates!A4:A50,1) -> 46215 | K3: =COUNTIFS([1]EDI!$S$2:$S$10000,"Ahmed Ali", [1]EDI!$Q$2:$Q$10000, "In Progress", [1]EDI!$I$2:$I$10000,"Forms") -> 0 | L3: {=SUM(COUNTIFS([1]EDI!$S$2:$S$10000,"Ahmed Ali", [1]EDI!$Q$2:$Q$10000,"In Progress", [1]EDI!$N$2:$N$10000,{"Mapping","Dataset Validation"}, [1]EDI!$I$2:$I$10000,"Forms"))} -> 0 | M3: =COUNTIFS([1]EDI!$S$2:$S$10000,"Ahmed Ali", [1]EDI!$Q$2:$Q$10000, "In Progress", [1]EDI!$N$2:$N$10000,"Testing", [1]EDI!$I$2:$I$10000,"Forms") -> 0 | N3: =COUNTIFS([1]EDI!$S$2:$S$10000,"Ahmed Ali", [1]EDI!$Q$2:$Q$10000, "In Progress", [1]EDI!$P$2:$P$10000,"Migration Testing", [1]EDI!$I$2:$I$10000,"Forms") -> 0 | O3: =COUNTIFS([1]EDI!$S$2:$S$10000,"Ahmed Ali", [1]EDI!$Q$2:$Q$10000, "Live", [1]EDI!$P$2:$P$10000,"Production", [1]EDI!$I$2:$I$10000,"Forms") -> 1 | Q3: =C3+K3 -> 25 | R3: =COUNTIFS( [1]EDI!$S$2:$S$10000,"Ahmed Ali", [1]EDI!$L$2:$L$10000,"<>", [1]EDI!$R$2:$R$10000,">="&DATE(2025,1,1), [1]EDI!$R$2:$R$10000,"<"&DATE(2026,1,1), [1]EDI!$I$2:$I$10000,"EDI" ) -> 49 | S3: =COUNTIFS( [1]EDI!$S$2:$S$10000,"Ahmed Ali", [1]EDI!$L$2:$L$10000,"<>", [1]EDI!$R$2:$R$10000,">="&DATE(2026,1,1), [1]EDI!$I$2:$I$10000,"EDI" ) -> 33
A4: Alaa Yehia | C4: =SUM(D4:G4) -> 20 | D4: =COUNTIFS([1]EDI!$S$2:$S$10000,"Alaa Yehia", [1]EDI!$Q$2:$Q$10000, "In Progress", [1]EDI!$N$2:$N$10000,"DataSet Validation", [1]EDI!$L$2:$L$10000,"", [1]EDI!$I$2:$I$10000,"EDI") -> 1 | E4: =COUNTIFS([1]EDI!$S$2:$S$10000,"Alaa Yehia", [1]EDI!$Q$2:$Q$10000, "In Progress", [1]EDI!$N$2:$N$10000,"Dataset Validation", [1]EDI!$L$2:$L$10000, "<>", [1]EDI!$I$2:$I$10000,"EDI") -> 0 | F4: =COUNTIFS([1]EDI!$S$2:$S$10000,"Alaa Yehia", [1]EDI!$Q$2:$Q$10000, "In Progress", [1]EDI!$N$2:$N$10000,"Mapping", [1]EDI!$I$2:$I$10000,"EDI") -> 3 | G4: =COUNTIFS([1]EDI!$S$2:$S$10000,"Alaa Yehia", [1]EDI!$Q$2:$Q$10000, "In Progress", [1]EDI!$N$2:$N$10000,"Testing", [1]EDI!$I$2:$I$10000,"EDI") -> 16 | H4: =COUNTIFS([1]EDI!$S$2:$S$10000,"Alaa Yehia", [1]EDI!$Q$2:$Q$10000, "In Progress", [1]EDI!$N$2:$N$10000,"Ready For Production", [1]EDI!$I$2:$I$10000,"EDI") -> 0 | I4: =LARGE(Dates!B4:B50,1) -> 46215 | K4: =COUNTIFS([1]EDI!$S$2:$S$10000,"Alaa Yehia", [1]EDI!$Q$2:$Q$10000, "In Progress", [1]EDI!$I$2:$I$10000,"Forms") -> 3 | L4: {=SUM(COUNTIFS([1]EDI!$S$2:$S$10000,"Alaa Yehia", [1]EDI!$Q$2:$Q$10000,"In Progress", [1]EDI!$N$2:$N$10000,{"Mapping","Dataset Validation"}, [1]EDI!$I$2:$I$10000,"Forms"))} -> 2 | M4: =COUNTIFS([1]EDI!$S$2:$S$10000,"Alaa Yehia", [1]EDI!$Q$2:$Q$10000, "In Progress", [1]EDI!$N$2:$N$10000,"Testing", [1]EDI!$I$2:$I$10000,"Forms") -> 1 | N4: =COUNTIFS([1]EDI!$S$2:$S$10000,"Alaa Yehia", [1]EDI!$Q$2:$Q$10000, "In Progress", [1]EDI!$P$2:$P$10000,"Migration Testing", [1]EDI!$I$2:$I$10000,"Forms") -> 0 | O4: =COUNTIFS([1]EDI!$S$2:$S$10000,"Alaa Yehia", [1]EDI!$Q$2:$Q$10000, "Live", [1]EDI!$P$2:$P$10000,"Production", [1]EDI!$I$2:$I$10000,"Forms") -> 1 | P4: =LARGE('Dates-Forms'!B4:B50,1) -> 46210 | Q4: =C4+K4 -> 23 | R4: =COUNTIFS( [1]EDI!$S$2:$S$10000,"Alaa Yehia", [1]EDI!$L$2:$L$10000,"<>", [1]EDI!$R$2:$R$10000,">="&DATE(2025,1,1), [1]EDI!$R$2:$R$10000,"<"&DATE(2026,1,1), [1]EDI!$I$2:$I$10000,"EDI" ) -> 60 | S4: =COUNTIFS( [1]EDI!$S$2:$S$10000,"Alaa Yehia", [1]EDI!$L$2:$L$10000,"<>", [1]EDI!$R$2:$R$10000,">="&DATE(2026,1,1), [1]EDI!$I$2:$I$10000,"EDI" ) -> 53
A5: Andrew Ramy | C5: =SUM(D5:G5) -> 27 | D5: =COUNTIFS([1]EDI!$S$2:$S$10000,"Andrew Ramy", [1]EDI!$Q$2:$Q$10000, "In Progress", [1]EDI!$N$2:$N$10000,"DataSet Validation", [1]EDI!$L$2:$L$10000,"", [1]EDI!$I$2:$I$10000,"EDI") -> 1 | E5: =COUNTIFS([1]EDI!$S$2:$S$10000,"Andrew Ramy", [1]EDI!$Q$2:$Q$10000, "In Progress", [1]EDI!$N$2:$N$10000,"Dataset Validation", [1]EDI!$L$2:$L$10000, "<>", [1]EDI!$I$2:$I$10000,"EDI") -> 0 | F5: =COUNTIFS([1]EDI!$S$2:$S$10000,"Andrew Ramy", [1]EDI!$Q$2:$Q$10000, "In Progress", [1]EDI!$N$2:$N$10000,"Mapping", [1]EDI!$I$2:$I$10000,"EDI") -> 0 | G5: =COUNTIFS([1]EDI!$S$2:$S$10000,"Andrew Ramy", [1]EDI!$Q$2:$Q$10000, "In Progress", [1]EDI!$N$2:$N$10000,"Testing", [1]EDI!$I$2:$I$10000,"EDI") -> 26 | H5: =COUNTIFS([1]EDI!$S$2:$S$10000,"Andrew Ramy", [1]EDI!$Q$2:$Q$10000, "In Progress", [1]EDI!$N$2:$N$10000,"Ready For Production", [1]EDI!$I$2:$I$10000,"EDI") -> 0 | I5: =LARGE(Dates!D4:D50,1) -> 46215 | K5: =COUNTIFS([1]EDI!$S$2:$S$10000,"Andrew Ramy", [1]EDI!$Q$2:$Q$10000, "In Progress", [1]EDI!$I$2:$I$10000,"Forms") -> 0 | L5: {=SUM(COUNTIFS([1]EDI!$S$2:$S$10000,"Andrew Ramy", [1]EDI!$Q$2:$Q$10000,"In Progress", [1]EDI!$N$2:$N$10000,{"Mapping","Dataset Validation"}, [1]EDI!$I$2:$I$10000,"Forms"))} -> 0 | M5: =COUNTIFS([1]EDI!$S$2:$S$10000,"Andrew Ramy", [1]EDI!$Q$2:$Q$10000, "In Progress", [1]EDI!$N$2:$N$10000,"Testing", [1]EDI!$I$2:$I$10000,"Forms") -> 0 | N5: =COUNTIFS([1]EDI!$S$2:$S$10000,"Andrew Ramy", [1]EDI!$Q$2:$Q$10000, "In Progress", [1]EDI!$P$2:$P$10000,"Migration Testing", [1]EDI!$I$2:$I$10000,"Forms") -> 0 | O5: =COUNTIFS([1]EDI!$S$2:$S$10000,"Andrew Ramy", [1]EDI!$Q$2:$Q$10000, "Live", [1]EDI!$P$2:$P$10000,"Production", [1]EDI!$I$2:$I$10000,"Forms") -> 0 | Q5: =C5+K5 -> 27 | R5: =COUNTIFS( [1]EDI!$S$2:$S$10000,"Andrew Ramy", [1]EDI!$L$2:$L$10000,"<>", [1]EDI!$R$2:$R$10000,">="&DATE(2025,1,1), [1]EDI!$R$2:$R$10000,"<"&DATE(2026,1,1), [1]EDI!$I$2:$I$10000,"EDI" ) -> 56 | S5: =COUNTIFS( [1]EDI!$S$2:$S$10000,"Andrew Ramy", [1]EDI!$L$2:$L$10000,"<>", [1]EDI!$R$2:$R$10000,">="&DATE(2026,1,1), [1]EDI!$I$2:$I$10000,"EDI" ) -> 49
A6: Aya Fathy | C6: =SUM(D6:G6) -> 21 | D6: =COUNTIFS([1]EDI!$S$2:$S$10000,"Aya Fathy", [1]EDI!$Q$2:$Q$10000, "In Progress", [1]EDI!$N$2:$N$10000,"DataSet Validation", [1]EDI!$L$2:$L$10000,"", [1]EDI!$I$2:$I$10000,"EDI") -> 0 | E6: =COUNTIFS([1]EDI!$S$2:$S$10000,"Aya Fathy", [1]EDI!$Q$2:$Q$10000, "In Progress", [1]EDI!$N$2:$N$10000,"Dataset Validation", [1]EDI!$L$2:$L$10000, "<>", [1]EDI!$I$2:$I$10000,"EDI") -> 0 | F6: =COUNTIFS([1]EDI!$S$2:$S$10000,"Aya Fathy", [1]EDI!$Q$2:$Q$10000, "In Progress", [1]EDI!$N$2:$N$10000,"Mapping", [1]EDI!$I$2:$I$10000,"EDI") -> 2 | G6: =COUNTIFS([1]EDI!$S$2:$S$10000,"Aya Fathy", [1]EDI!$Q$2:$Q$10000, "In Progress", [1]EDI!$N$2:$N$10000,"Testing", [1]EDI!$I$2:$I$10000,"EDI") -> 19 | H6: =COUNTIFS([1]EDI!$S$2:$S$10000,"Aya Fathy", [1]EDI!$Q$2:$Q$10000, "In Progress", [1]EDI!$N$2:$N$10000,"Ready For Production", [1]EDI!$I$2:$I$10000,"EDI") -> 0 | I6: =LARGE(Dates!E4:E50,1) -> 46204 | K6: =COUNTIFS([1]EDI!$S$2:$S$10000,"Aya Fathy", [1]EDI!$Q$2:$Q$10000, "In Progress", [1]EDI!$I$2:$I$10000,"Forms") -> 1 | L6: {=SUM(COUNTIFS([1]EDI!$S$2:$S$10000,"Aya Fathy", [1]EDI!$Q$2:$Q$10000,"In Progress", [1]EDI!$N$2:$N$10000,{"Mapping","Dataset Validation"}, [1]EDI!$I$2:$I$10000,"Forms"))} -> 0 | M6: =COUNTIFS([1]EDI!$S$2:$S$10000,"Aya Fathy", [1]EDI!$Q$2:$Q$10000, "In Progress", [1]EDI!$N$2:$N$10000,"Testing", [1]EDI!$I$2:$I$10000,"Forms") -> 1 | N6: =COUNTIFS([1]EDI!$S$2:$S$10000,"Aya Fathy", [1]EDI!$Q$2:$Q$10000, "In Progress", [1]EDI!$P$2:$P$10000,"Migration Testing", [1]EDI!$I$2:$I$10000,"Forms") -> 0 | O6: =COUNTIFS([1]EDI!$S$2:$S$10000,"Aya Fathy", [1]EDI!$Q$2:$Q$10000, "Live", [1]EDI!$P$2:$P$10000,"Production", [1]EDI!$I$2:$I$10000,"Forms") -> 1 | P6: =LARGE('Dates-Forms'!E4:E50,1) -> 46210 | Q6: =C6+K6 -> 22 | R6: =COUNTIFS( [1]EDI!$S$2:$S$10000,"Aya Fathy", [1]EDI!$L$2:$L$10000,"<>", [1]EDI!$R$2:$R$10000,">="&DATE(2025,1,1), [1]EDI!$R$2:$R$10000,"<"&DATE(2026,1,1), [1]EDI!$I$2:$I$10000,"EDI" ) -> 37 | S6: =COUNTIFS( [1]EDI!$S$2:$S$10000,"Aya Fathy", [1]EDI!$L$2:$L$10000,"<>", [1]EDI!$R$2:$R$10000,">="&DATE(2026,1,1), [1]EDI!$I$2:$I$10000,"EDI" ) -> 60
A7: Josephine Ossama | C7: =SUM(D7:G7) -> 22 | D7: =COUNTIFS([1]EDI!$S$2:$S$10000,"Josephine Ossama", [1]EDI!$Q$2:$Q$10000, "In Progress", [1]EDI!$N$2:$N$10000,"DataSet Validation", [1]EDI!$L$2:$L$10000,"", [1]EDI!$I$2:$I$10000,"EDI") -> 0 | E7: =COUNTIFS([1]EDI!$S$2:$S$10000,"Josephine Ossama", [1]EDI!$Q$2:$Q$10000, "In Progress", [1]EDI!$N$2:$N$10000,"Dataset Validation", [1]EDI!$L$2:$L$10000, "<>", [1]EDI!$I$2:$I$10000,"EDI") -> 0 | F7: =COUNTIFS([1]EDI!$S$2:$S$10000,"Josephine Ossama", [1]EDI!$Q$2:$Q$10000, "In Progress", [1]EDI!$N$2:$N$10000,"Mapping", [1]EDI!$I$2:$I$10000,"EDI") -> 8 | G7: =COUNTIFS([1]EDI!$S$2:$S$10000,"Josephine Ossama", [1]EDI!$Q$2:$Q$10000, "In Progress", [1]EDI!$N$2:$N$10000,"Testing", [1]EDI!$I$2:$I$10000,"EDI") -> 14 | H7: =COUNTIFS([1]EDI!$S$2:$S$10000,"Josephine Ossama", [1]EDI!$Q$2:$Q$10000, "In Progress", [1]EDI!$N$2:$N$10000,"Ready For Production", [1]EDI!$I$2:$I$10000,"EDI") -> 1 | I7: =LARGE(Dates!Y4:Y50,1) -> 46215 | K7: =COUNTIFS([1]EDI!$S$2:$S$10000,"Josephine Ossama", [1]EDI!$Q$2:$Q$10000, "In Progress", [1]EDI!$I$2:$I$10000,"Forms") -> 0 | L7: {=SUM(COUNTIFS([1]EDI!$S$2:$S$10000,"Josephine Ossama", [1]EDI!$Q$2:$Q$10000,"In Progress", [1]EDI!$N$2:$N$10000,{"Mapping","Dataset Validation"}, [1]EDI!$I$2:$I$10000,"Forms"))} -> 0 | M7: =COUNTIFS([1]EDI!$S$2:$S$10000,"Josephine Ossama", [1]EDI!$Q$2:$Q$10000, "In Progress", [1]EDI!$N$2:$N$10000,"Testing", [1]EDI!$I$2:$I$10000,"Forms") -> 0 | N7: =COUNTIFS([1]EDI!$S$2:$S$10000,"Josephine Ossama", [1]EDI!$Q$2:$Q$10000, "In Progress", [1]EDI!$P$2:$P$10000,"Migration Testing", [1]EDI!$I$2:$I$10000,"Forms") -> 0 | O7: =COUNTIFS([1]EDI!$S$2:$S$10000,"Josephine Ossama", [1]EDI!$Q$2:$Q$10000, "Live", [1]EDI!$P$2:$P$10000,"Production", [1]EDI!$I$2:$I$10000,"Forms") -> 0 | Q7: =C7+K7 -> 22 | R7: =COUNTIFS( [1]EDI!$S$2:$S$10000,"Josephine Ossama", [1]EDI!$L$2:$L$10000,"<>", [1]EDI!$R$2:$R$10000,">="&DATE(2025,1,1), [1]EDI!$R$2:$R$10000,"<"&DATE(2026,1,1), [1]EDI!$I$2:$I$10000,"EDI" ) -> 44 | S7: =COUNTIFS( [1]EDI!$S$2:$S$10000,"Josephine Ossama", [1]EDI!$L$2:$L$10000,"<>", [1]EDI!$R$2:$R$10000,">="&DATE(2026,1,1), [1]EDI!$I$2:$I$10000,"EDI" ) -> 29
A8: Karen Ramy | C8: =SUM(D8:G8) -> 16 | D8: =COUNTIFS([1]EDI!$S$2:$S$10000,"Karen Ramy", [1]EDI!$Q$2:$Q$10000, "In Progress", [1]EDI!$N$2:$N$10000,"DataSet Validation", [1]EDI!$L$2:$L$10000,"", [1]EDI!$I$2:$I$10000,"EDI") -> 0 | E8: =COUNTIFS([1]EDI!$S$2:$S$10000,"Karen Ramy", [1]EDI!$Q$2:$Q$10000, "In Progress", [1]EDI!$N$2:$N$10000,"Dataset Validation", [1]EDI!$L$2:$L$10000, "<>", [1]EDI!$I$2:$I$10000,"EDI") -> 0 | F8: =COUNTIFS([1]EDI!$S$2:$S$10000,"Karen Ramy", [1]EDI!$Q$2:$Q$10000, "In Progress", [1]EDI!$N$2:$N$10000,"Mapping", [1]EDI!$I$2:$I$10000,"EDI") -> 11 | G8: =COUNTIFS([1]EDI!$S$2:$S$10000,"Karen Ramy", [1]EDI!$Q$2:$Q$10000, "In Progress", [1]EDI!$N$2:$N$10000,"Testing", [1]EDI!$I$2:$I$10000,"EDI") -> 5 | H8: =COUNTIFS([1]EDI!$S$2:$S$10000,"Karen Ramy", [1]EDI!$Q$2:$Q$10000, "In Progress", [1]EDI!$N$2:$N$10000,"Ready For Production", [1]EDI!$I$2:$I$10000,"EDI") -> 1 | I8: =LARGE(Dates!R4:R50,1) -> 46211 | K8: =COUNTIFS([1]EDI!$S$2:$S$10000,"Karen Ramy", [1]EDI!$Q$2:$Q$10000, "In Progress", [1]EDI!$I$2:$I$10000,"Forms") -> 0 | L8: {=SUM(COUNTIFS([1]EDI!$S$2:$S$10000,"Karen Ramy", [1]EDI!$Q$2:$Q$10000,"In Progress", [1]EDI!$N$2:$N$10000,{"Mapping","Dataset Validation"}, [1]EDI!$I$2:$I$10000,"Forms"))} -> 0 | M8: =COUNTIFS([1]EDI!$S$2:$S$10000,"Karen Ramy", [1]EDI!$Q$2:$Q$10000, "In Progress", [1]EDI!$N$2:$N$10000,"Testing", [1]EDI!$I$2:$I$10000,"Forms") -> 0 | N8: =COUNTIFS([1]EDI!$S$2:$S$10000,"Karen Ramy", [1]EDI!$Q$2:$Q$10000, "In Progress", [1]EDI!$P$2:$P$10000,"Migration Testing", [1]EDI!$I$2:$I$10000,"Forms") -> 0 | O8: =COUNTIFS([1]EDI!$S$2:$S$10000,"Karen Ramy", [1]EDI!$Q$2:$Q$10000, "Live", [1]EDI!$P$2:$P$10000,"Production", [1]EDI!$I$2:$I$10000,"Forms") -> 2 | Q8: =C8+K8 -> 16 | R8: =COUNTIFS( [1]EDI!$S$2:$S$10000,"Karen Ramy", [1]EDI!$L$2:$L$10000,"<>", [1]EDI!$R$2:$R$10000,">="&DATE(2025,1,1), [1]EDI!$R$2:$R$10000,"<"&DATE(2026,1,1), [1]EDI!$I$2:$I$10000,"EDI" ) -> 52 | S8: =COUNTIFS( [1]EDI!$S$2:$S$10000,"Karen Ramy", [1]EDI!$L$2:$L$10000,"<>", [1]EDI!$R$2:$R$10000,">="&DATE(2026,1,1), [1]EDI!$I$2:$I$10000,"EDI" ) -> 41
A9: Mark Albert | C9: =SUM(D9:G9) -> 22 | D9: =COUNTIFS([1]EDI!$S$2:$S$10000,"Mark Albert", [1]EDI!$Q$2:$Q$10000, "In Progress", [1]EDI!$N$2:$N$10000,"DataSet Validation", [1]EDI!$L$2:$L$10000,"", [1]EDI!$I$2:$I$10000,"EDI") -> 0 | E9: =COUNTIFS([1]EDI!$S$2:$S$10000,"Mark Albert", [1]EDI!$Q$2:$Q$10000, "In Progress", [1]EDI!$N$2:$N$10000,"Dataset Validation", [1]EDI!$L$2:$L$10000, "<>", [1]EDI!$I$2:$I$10000,"EDI") -> 0 | F9: =COUNTIFS([1]EDI!$S$2:$S$10000,"Mark Albert", [1]EDI!$Q$2:$Q$10000, "In Progress", [1]EDI!$N$2:$N$10000,"Mapping", [1]EDI!$I$2:$I$10000,"EDI") -> 10 | G9: =COUNTIFS([1]EDI!$S$2:$S$10000,"Mark Albert", [1]EDI!$Q$2:$Q$10000, "In Progress", [1]EDI!$N$2:$N$10000,"Testing", [1]EDI!$I$2:$I$10000,"EDI") -> 12 | H9: =COUNTIFS([1]EDI!$S$2:$S$10000,"Mark Albert", [1]EDI!$Q$2:$Q$10000, "In Progress", [1]EDI!$N$2:$N$10000,"Ready For Production", [1]EDI!$I$2:$I$10000,"EDI") -> 0 | I9: =LARGE(Dates!X4:X50,1) -> 46215 | K9: =COUNTIFS([1]EDI!$S$2:$S$10000,"Mark Albert", [1]EDI!$Q$2:$Q$10000, "In Progress", [1]EDI!$I$2:$I$10000,"Forms") -> 2 | L9: {=SUM(COUNTIFS([1]EDI!$S$2:$S$10000,"Mark Albert", [1]EDI!$Q$2:$Q$10000,"In Progress", [1]EDI!$N$2:$N$10000,{"Mapping","Dataset Validation"}, [1]EDI!$I$2:$I$10000,"Forms"))} -> 0 | M9: =COUNTIFS([1]EDI!$S$2:$S$10000,"Mark Albert", [1]EDI!$Q$2:$Q$10000, "In Progress", [1]EDI!$N$2:$N$10000,"Testing", [1]EDI!$I$2:$I$10000,"Forms") -> 0 | N9: =COUNTIFS([1]EDI!$S$2:$S$10000,"Mark Albert", [1]EDI!$Q$2:$Q$10000, "In Progress", [1]EDI!$P$2:$P$10000,"Migration Testing", [1]EDI!$I$2:$I$10000,"Forms") -> 0 | O9: =COUNTIFS([1]EDI!$S$2:$S$10000,"Mark Albert", [1]EDI!$Q$2:$Q$10000, "Live", [1]EDI!$P$2:$P$10000,"Production", [1]EDI!$I$2:$I$10000,"Forms") -> 1 | P9: =LARGE('Dates-Forms'!X4:X50,1) -> 46176 | Q9: =C9+K9 -> 24 | R9: =COUNTIFS( [1]EDI!$S$2:$S$10000,"Mark Albert", [1]EDI!$L$2:$L$10000,"<>", [1]EDI!$R$2:$R$10000,">="&DATE(2025,1,1), [1]EDI!$R$2:$R$10000,"<"&DATE(2026,1,1), [1]EDI!$I$2:$I$10000,"EDI" ) -> 38 | S9: =COUNTIFS( [1]EDI!$S$2:$S$10000,"Mark Albert", [1]EDI!$L$2:$L$10000,"<>", [1]EDI!$R$2:$R$10000,">="&DATE(2026,1,1), [1]EDI!$I$2:$I$10000,"EDI" ) -> 43
A10: Marwan Tawfik | C10: =SUM(D10:G10) -> 6 | D10: =COUNTIFS([1]EDI!$S$2:$S$10000,"Marwan Tawfik", [1]EDI!$Q$2:$Q$10000, "In Progress", [1]EDI!$N$2:$N$10000,"DataSet Validation", [1]EDI!$L$2:$L$10000,"", [1]EDI!$I$2:$I$10000,"EDI") -> 0 | E10: =COUNTIFS([1]EDI!$S$2:$S$10000,"Marwan Tawfik", [1]EDI!$Q$2:$Q$10000, "In Progress", [1]EDI!$N$2:$N$10000,"Dataset Validation", [1]EDI!$L$2:$L$10000, "<>", [1]EDI!$I$2:$I$10000,"EDI") -> 0 | F10: =COUNTIFS([1]EDI!$S$2:$S$10000,"Marwan Tawfik", [1]EDI!$Q$2:$Q$10000, "In Progress", [1]EDI!$N$2:$N$10000,"Mapping", [1]EDI!$I$2:$I$10000,"EDI") -> 0 | G10: =COUNTIFS([1]EDI!$S$2:$S$10000,"Marwan Tawfik", [1]EDI!$Q$2:$Q$10000, "In Progress", [1]EDI!$N$2:$N$10000,"Testing", [1]EDI!$I$2:$I$10000,"EDI") -> 6 | H10: =COUNTIFS([1]EDI!$S$2:$S$10000,"Marwan Tawfik", [1]EDI!$Q$2:$Q$10000, "In Progress", [1]EDI!$N$2:$N$10000,"Ready For Production", [1]EDI!$I$2:$I$10000,"EDI") -> 0 | I10: =LARGE(Dates!I4:I50,1) -> 46132 | K10: =COUNTIFS([1]EDI!$S$2:$S$10000,"Marwan Tawfik", [1]EDI!$Q$2:$Q$10000, "In Progress", [1]EDI!$I$2:$I$10000,"Forms") -> 0 | L10: {=SUM(COUNTIFS([1]EDI!$S$2:$S$10000,"Marwan Tawfik", [1]EDI!$Q$2:$Q$10000,"In Progress", [1]EDI!$N$2:$N$10000,{"Mapping","Dataset Validation"}, [1]EDI!$I$2:$I$10000,"Forms"))} -> 0 | M10: =COUNTIFS([1]EDI!$S$2:$S$10000,"Marwan Tawfik", [1]EDI!$Q$2:$Q$10000, "In Progress", [1]EDI!$N$2:$N$10000,"Testing", [1]EDI!$I$2:$I$10000,"Forms") -> 0 | N10: =COUNTIFS([1]EDI!$S$2:$S$10000,"Marwan Tawfik", [1]EDI!$Q$2:$Q$10000, "In Progress", [1]EDI!$P$2:$P$10000,"Migration Testing", [1]EDI!$I$2:$I$10000,"Forms") -> 0 | O10: =COUNTIFS([1]EDI!$S$2:$S$10000,"Marwan Tawfik", [1]EDI!$Q$2:$Q$10000, "Live", [1]EDI!$P$2:$P$10000,"Production", [1]EDI!$I$2:$I$10000,"Forms") -> 0 | Q10: =C10+K10 -> 6 | R10: =COUNTIFS( [1]EDI!$S$2:$S$10000,"Marwan Tawfik", [1]EDI!$L$2:$L$10000,"<>", [1]EDI!$R$2:$R$10000,">="&DATE(2025,1,1), [1]EDI!$R$2:$R$10000,"<"&DATE(2026,1,1), [1]EDI!$I$2:$I$10000,"EDI" ) -> 46 | S10: =COUNTIFS( [1]EDI!$S$2:$S$10000,"Marwan Tawfik", [1]EDI!$L$2:$L$10000,"<>", [1]EDI!$R$2:$R$10000,">="&DATE(2026,1,1), [1]EDI!$I$2:$I$10000,"EDI" ) -> 17
A11: Mina Adel | C11: =SUM(D11:G11) -> 1 | D11: =COUNTIFS([1]EDI!$S$2:$S$10000,"Mina Adel", [1]EDI!$Q$2:$Q$10000, "In Progress", [1]EDI!$N$2:$N$10000,"DataSet Validation", [1]EDI!$L$2:$L$10000,"", [1]EDI!$I$2:$I$10000,"EDI") -> 0 | E11: =COUNTIFS([1]EDI!$S$2:$S$10000,"Mina Adel", [1]EDI!$Q$2:$Q$10000, "In Progress", [1]EDI!$N$2:$N$10000,"Dataset Validation", [1]EDI!$L$2:$L$10000, "<>", [1]EDI!$I$2:$I$10000,"EDI") -> 0 | F11: =COUNTIFS([1]EDI!$S$2:$S$10000,"Mina Adel", [1]EDI!$Q$2:$Q$10000, "In Progress", [1]EDI!$N$2:$N$10000,"Mapping", [1]EDI!$I$2:$I$10000,"EDI") -> 1 | G11: =COUNTIFS([1]EDI!$S$2:$S$10000,"Mina Adel", [1]EDI!$Q$2:$Q$10000, "In Progress", [1]EDI!$N$2:$N$10000,"Testing", [1]EDI!$I$2:$I$10000,"EDI") -> 0 | H11: =COUNTIFS([1]EDI!$S$2:$S$10000,"Mina Adel", [1]EDI!$Q$2:$Q$10000, "In Progress", [1]EDI!$N$2:$N$10000,"Ready For Production", [1]EDI!$I$2:$I$10000,"EDI") -> 0 | I11: =LARGE(Dates!J4:J50,1) -> 45249 | K11: =COUNTIFS([1]EDI!$S$2:$S$10000,"Mina Adel", [1]EDI!$Q$2:$Q$10000, "In Progress", [1]EDI!$I$2:$I$10000,"Forms") -> 0 | L11: {=SUM(COUNTIFS([1]EDI!$S$2:$S$10000,"Mina Adel", [1]EDI!$Q$2:$Q$10000,"In Progress", [1]EDI!$N$2:$N$10000,{"Mapping","Dataset Validation"}, [1]EDI!$I$2:$I$10000,"Forms"))} -> 0 | M11: =COUNTIFS([1]EDI!$S$2:$S$10000,"Mina Adel", [1]EDI!$Q$2:$Q$10000, "In Progress", [1]EDI!$N$2:$N$10000,"Testing", [1]EDI!$I$2:$I$10000,"Forms") -> 0 | N11: =COUNTIFS([1]EDI!$S$2:$S$10000,"Mina Adel", [1]EDI!$Q$2:$Q$10000, "In Progress", [1]EDI!$P$2:$P$10000,"Migration Testing", [1]EDI!$I$2:$I$10000,"Forms") -> 0 | O11: =COUNTIFS([1]EDI!$S$2:$S$10000,"Mina Adel", [1]EDI!$Q$2:$Q$10000, "Live", [1]EDI!$P$2:$P$10000,"Production", [1]EDI!$I$2:$I$10000,"Forms") -> 0 | Q11: =C11+K11 -> 1 | R11: =COUNTIFS( [1]EDI!$S$2:$S$10000,"Mina Adel", [1]EDI!$L$2:$L$10000,"<>", [1]EDI!$R$2:$R$10000,">="&DATE(2025,1,1), [1]EDI!$R$2:$R$10000,"<"&DATE(2026,1,1), [1]EDI!$I$2:$I$10000,"EDI" ) -> 14 | S11: =COUNTIFS( [1]EDI!$S$2:$S$10000,"Mina Adel", [1]EDI!$L$2:$L$10000,"<>", [1]EDI!$R$2:$R$10000,">="&DATE(2026,1,1), [1]EDI!$I$2:$I$10000,"EDI" ) -> 0
A12: Mina George | C12: =SUM(D12:G12) -> 0 | D12: =COUNTIFS([1]EDI!$S$2:$S$10000,"Mina George", [1]EDI!$Q$2:$Q$10000, "In Progress", [1]EDI!$N$2:$N$10000,"DataSet Validation", [1]EDI!$L$2:$L$10000,"", [1]EDI!$I$2:$I$10000,"EDI") -> 0 | E12: =COUNTIFS([1]EDI!$S$2:$S$10000,"Mina George", [1]EDI!$Q$2:$Q$10000, "In Progress", [1]EDI!$N$2:$N$10000,"Dataset Validation", [1]EDI!$L$2:$L$10000, "<>", [1]EDI!$I$2:$I$10000,"EDI") -> 0 | F12: =COUNTIFS([1]EDI!$S$2:$S$10000,"Mina George", [1]EDI!$Q$2:$Q$10000, "In Progress", [1]EDI!$N$2:$N$10000,"Mapping", [1]EDI!$I$2:$I$10000,"EDI") -> 0 | G12: =COUNTIFS([1]EDI!$S$2:$S$10000,"Mina George", [1]EDI!$Q$2:$Q$10000, "In Progress", [1]EDI!$N$2:$N$10000,"Testing", [1]EDI!$I$2:$I$10000,"EDI") -> 0 | H12: =COUNTIFS([1]EDI!$S$2:$S$10000,"Mina George", [1]EDI!$Q$2:$Q$10000, "In Progress", [1]EDI!$N$2:$N$10000,"Ready For Production", [1]EDI!$I$2:$I$10000,"EDI") -> 0 | I12: =LARGE(Dates!K4:K50,1) -> #NUM! | K12: =COUNTIFS([1]EDI!$S$2:$S$10000,"Mina George", [1]EDI!$Q$2:$Q$10000, "In Progress", [1]EDI!$I$2:$I$10000,"Forms") -> 0 | L12: {=SUM(COUNTIFS([1]EDI!$S$2:$S$10000,"Mina George", [1]EDI!$Q$2:$Q$10000,"In Progress", [1]EDI!$N$2:$N$10000,{"Mapping","Dataset Validation"}, [1]EDI!$I$2:$I$10000,"Forms"))} -> 0 | M12: =COUNTIFS([1]EDI!$S$2:$S$10000,"Mina George", [1]EDI!$Q$2:$Q$10000, "In Progress", [1]EDI!$N$2:$N$10000,"Testing", [1]EDI!$I$2:$I$10000,"Forms") -> 0 | N12: =COUNTIFS([1]EDI!$S$2:$S$10000,"Mina George", [1]EDI!$Q$2:$Q$10000, "In Progress", [1]EDI!$P$2:$P$10000,"Migration Testing", [1]EDI!$I$2:$I$10000,"Forms") -> 0 | O12: =COUNTIFS([1]EDI!$S$2:$S$10000,"Mina George", [1]EDI!$Q$2:$Q$10000, "Live", [1]EDI!$P$2:$P$10000,"Production", [1]EDI!$I$2:$I$10000,"Forms") -> 0 | Q12: =C12+K12 -> 0 | R12: =COUNTIFS( [1]EDI!$S$2:$S$10000,"Mina George", [1]EDI!$L$2:$L$10000,"<>", [1]EDI!$R$2:$R$10000,">="&DATE(2025,1,1), [1]EDI!$R$2:$R$10000,"<"&DATE(2026,1,1), [1]EDI!$I$2:$I$10000,"EDI" ) -> 16 | S12: =COUNTIFS( [1]EDI!$S$2:$S$10000,"Mina George", [1]EDI!$L$2:$L$10000,"<>", [1]EDI!$R$2:$R$10000,">="&DATE(2026,1,1), [1]EDI!$I$2:$I$10000,"EDI" ) -> 0
A13: Karim Tarek | C13: =SUM(D13:G13) -> 0 | D13: =COUNTIFS([1]EDI!$S$2:$S$10000,"Karim Tarek", [1]EDI!$Q$2:$Q$10000, "In Progress", [1]EDI!$N$2:$N$10000,"DataSet Validation", [1]EDI!$L$2:$L$10000,"", [1]EDI!$I$2:$I$10000,"EDI") -> 0 | E13: =COUNTIFS([1]EDI!$S$2:$S$10000,"Karim Tarek", [1]EDI!$Q$2:$Q$10000, "In Progress", [1]EDI!$N$2:$N$10000,"Dataset Validation", [1]EDI!$L$2:$L$10000, "<>", [1]EDI!$I$2:$I$10000,"EDI") -> 0 | F13: =COUNTIFS([1]EDI!$S$2:$S$10000,"Karim Tarek", [1]EDI!$Q$2:$Q$10000, "In Progress", [1]EDI!$N$2:$N$10000,"Mapping", [1]EDI!$I$2:$I$10000,"EDI") -> 0 | G13: =COUNTIFS([1]EDI!$S$2:$S$10000,"Karim Tarek", [1]EDI!$Q$2:$Q$10000, "In Progress", [1]EDI!$N$2:$N$10000,"Testing", [1]EDI!$I$2:$I$10000,"EDI") -> 0 | H13: =COUNTIFS([1]EDI!$S$2:$S$10000,"Karim Tarek", [1]EDI!$Q$2:$Q$10000, "In Progress", [1]EDI!$N$2:$N$10000,"Ready For Production", [1]EDI!$I$2:$I$10000,"EDI") -> 0 | I13: =LARGE(Dates!S4:S50,1) -> 46198 | K13: =COUNTIFS([1]EDI!$S$2:$S$10000,"Karim Tarek", [1]EDI!$Q$2:$Q$10000, "In Progress", [1]EDI!$I$2:$I$10000,"Forms") -> 1 | L13: {=SUM(COUNTIFS([1]EDI!$S$2:$S$10000,"Karim Tarek", [1]EDI!$Q$2:$Q$10000,"In Progress", [1]EDI!$N$2:$N$10000,{"Mapping","Dataset Validation"}, [1]EDI!$I$2:$I$10000,"Forms"))} -> 0 | M13: =COUNTIFS([1]EDI!$S$2:$S$10000,"Karim Tarek", [1]EDI!$Q$2:$Q$10000, "In Progress", [1]EDI!$N$2:$N$10000,"Testing", [1]EDI!$I$2:$I$10000,"Forms") -> 0 | N13: =COUNTIFS([1]EDI!$S$2:$S$10000,"Karim Tarek", [1]EDI!$Q$2:$Q$10000, "In Progress", [1]EDI!$P$2:$P$10000,"Migration Testing", [1]EDI!$I$2:$I$10000,"Forms") -> 1 | O13: =COUNTIFS([1]EDI!$S$2:$S$10000,"Karim Tarek", [1]EDI!$Q$2:$Q$10000, "Live", [1]EDI!$P$2:$P$10000,"Production", [1]EDI!$I$2:$I$10000,"Forms") -> 0 | P13: =LARGE('Dates-Forms'!S4:S50,1) -> 46033 | Q13: =C13+K13 -> 1 | R13: =COUNTIFS( [1]EDI!$S$2:$S$10000,"Karim Tarek", [1]EDI!$L$2:$L$10000,"<>", [1]EDI!$R$2:$R$10000,">="&DATE(2025,1,1), [1]EDI!$R$2:$R$10000,"<"&DATE(2026,1,1), [1]EDI!$I$2:$I$10000,"EDI" ) -> 40 | S13: =COUNTIFS( [1]EDI!$S$2:$S$10000,"Karim Tarek", [1]EDI!$L$2:$L$10000,"<>", [1]EDI!$R$2:$R$10000,">="&DATE(2026,1,1), [1]EDI!$I$2:$I$10000,"EDI" ) -> 1
A14: Mirna Azmy | C14: =SUM(D14:G14) -> 25 | D14: =COUNTIFS([1]EDI!$S$2:$S$10000,"Mirna Azmy", [1]EDI!$Q$2:$Q$10000, "In Progress", [1]EDI!$N$2:$N$10000,"DataSet Validation", [1]EDI!$L$2:$L$10000,"", [1]EDI!$I$2:$I$10000,"EDI") -> 1 | E14: =COUNTIFS([1]EDI!$S$2:$S$10000,"Mirna Azmy", [1]EDI!$Q$2:$Q$10000, "In Progress", [1]EDI!$N$2:$N$10000,"Dataset Validation", [1]EDI!$L$2:$L$10000, "<>", [1]EDI!$I$2:$I$10000,"EDI") -> 1 | F14: =COUNTIFS([1]EDI!$S$2:$S$10000,"Mirna Azmy", [1]EDI!$Q$2:$Q$10000, "In Progress", [1]EDI!$N$2:$N$10000,"Mapping", [1]EDI!$I$2:$I$10000,"EDI") -> 6 | G14: =COUNTIFS([1]EDI!$S$2:$S$10000,"Mirna Azmy", [1]EDI!$Q$2:$Q$10000, "In Progress", [1]EDI!$N$2:$N$10000,"Testing", [1]EDI!$I$2:$I$10000,"EDI") -> 17 | H14: =COUNTIFS([1]EDI!$S$2:$S$10000,"Mirna Azmy", [1]EDI!$Q$2:$Q$10000, "In Progress", [1]EDI!$N$2:$N$10000,"Ready For Production", [1]EDI!$I$2:$I$10000,"EDI") -> 3 | I14: =LARGE(Dates!M4:M50,1) -> 46215 | K14: =COUNTIFS([1]EDI!$S$2:$S$10000,"Mirna Azmy", [1]EDI!$Q$2:$Q$10000, "In Progress", [1]EDI!$I$2:$I$10000,"Forms") -> 0 | L14: {=SUM(COUNTIFS([1]EDI!$S$2:$S$10000,"Mirna Azmy", [1]EDI!$Q$2:$Q$10000,"In Progress", [1]EDI!$N$2:$N$10000,{"Mapping","Dataset Validation"}, [1]EDI!$I$2:$I$10000,"Forms"))} -> 0 | M14: =COUNTIFS([1]EDI!$S$2:$S$10000,"Mirna Azmy", [1]EDI!$Q$2:$Q$10000, "In Progress", [1]EDI!$N$2:$N$10000,"Testing", [1]EDI!$I$2:$I$10000,"Forms") -> 0 | N14: =COUNTIFS([1]EDI!$S$2:$S$10000,"Mirna Azmy", [1]EDI!$Q$2:$Q$10000, "In Progress", [1]EDI!$P$2:$P$10000,"Migration Testing", [1]EDI!$I$2:$I$10000,"Forms") -> 0 | O14: =COUNTIFS([1]EDI!$S$2:$S$10000,"Mirna Azmy", [1]EDI!$Q$2:$Q$10000, "Live", [1]EDI!$P$2:$P$10000,"Production", [1]EDI!$I$2:$I$10000,"Forms") -> 2 | Q14: =C14+K14 -> 25 | R14: =COUNTIFS( [1]EDI!$S$2:$S$10000,"Mirna Azmy", [1]EDI!$L$2:$L$10000,"<>", [1]EDI!$R$2:$R$10000,">="&DATE(2025,1,1), [1]EDI!$R$2:$R$10000,"<"&DATE(2026,1,1), [1]EDI!$I$2:$I$10000,"EDI" ) -> 68 | S14: =COUNTIFS( [1]EDI!$S$2:$S$10000,"Mirna Azmy", [1]EDI!$L$2:$L$10000,"<>", [1]EDI!$R$2:$R$10000,">="&DATE(2026,1,1), [1]EDI!$I$2:$I$10000,"EDI" ) -> 56
A15: Omnia Abdelaziz | C15: =SUM(D15:G15) -> 21 | D15: =COUNTIFS([1]EDI!$S$2:$S$10000,"Omnia Abdelaziz", [1]EDI!$Q$2:$Q$10000, "In Progress", [1]EDI!$N$2:$N$10000,"DataSet Validation", [1]EDI!$L$2:$L$10000,"", [1]EDI!$I$2:$I$10000,"EDI") -> 0 | E15: =COUNTIFS([1]EDI!$S$2:$S$10000,"Omnia Abdelaziz", [1]EDI!$Q$2:$Q$10000, "In Progress", [1]EDI!$N$2:$N$10000,"Dataset Validation", [1]EDI!$L$2:$L$10000, "<>", [1]EDI!$I$2:$I$10000,"EDI") -> 0 | F15: =COUNTIFS([1]EDI!$S$2:$S$10000,"Omnia Abdelaziz", [1]EDI!$Q$2:$Q$10000, "In Progress", [1]EDI!$N$2:$N$10000,"Mapping", [1]EDI!$I$2:$I$10000,"EDI") -> 7 | G15: =COUNTIFS([1]EDI!$S$2:$S$10000,"Omnia Abdelaziz", [1]EDI!$Q$2:$Q$10000, "In Progress", [1]EDI!$N$2:$N$10000,"Testing", [1]EDI!$I$2:$I$10000,"EDI") -> 14 | H15: =COUNTIFS([1]EDI!$S$2:$S$10000,"Omnia Abdelaziz", [1]EDI!$Q$2:$Q$10000, "In Progress", [1]EDI!$N$2:$N$10000,"Ready For Production", [1]EDI!$I$2:$I$10000,"EDI") -> 3 | I15: =LARGE(Dates!P4:P50,1) -> 46215 | K15: =COUNTIFS([1]EDI!$S$2:$S$10000,"Omnia Abdelaziz", [1]EDI!$Q$2:$Q$10000, "In Progress", [1]EDI!$I$2:$I$10000,"Forms") -> 0 | L15: {=SUM(COUNTIFS([1]EDI!$S$2:$S$10000,"Omnia Abdelaziz", [1]EDI!$Q$2:$Q$10000,"In Progress", [1]EDI!$N$2:$N$10000,{"Mapping","Dataset Validation"}, [1]EDI!$I$2:$I$10000,"Forms"))} -> 0 | M15: =COUNTIFS([1]EDI!$S$2:$S$10000,"Omnia Abdelaziz", [1]EDI!$Q$2:$Q$10000, "In Progress", [1]EDI!$N$2:$N$10000,"Testing", [1]EDI!$I$2:$I$10000,"Forms") -> 0 | N15: =COUNTIFS([1]EDI!$S$2:$S$10000,"Omnia Abdelaziz", [1]EDI!$Q$2:$Q$10000, "In Progress", [1]EDI!$P$2:$P$10000,"Migration Testing", [1]EDI!$I$2:$I$10000,"Forms") -> 0 | O15: =COUNTIFS([1]EDI!$S$2:$S$10000,"Omnia Abdelaziz", [1]EDI!$Q$2:$Q$10000, "Live", [1]EDI!$P$2:$P$10000,"Production", [1]EDI!$I$2:$I$10000,"Forms") -> 3 | Q15: =C15+K15 -> 21 | R15: =COUNTIFS( [1]EDI!$S$2:$S$10000,"Omnia Abdelaziz", [1]EDI!$L$2:$L$10000,"<>", [1]EDI!$R$2:$R$10000,">="&DATE(2025,1,1), [1]EDI!$R$2:$R$10000,"<"&DATE(2026,1,1), [1]EDI!$I$2:$I$10000,"EDI" ) -> 61 | S15: =COUNTIFS( [1]EDI!$S$2:$S$10000,"Omnia Abdelaziz", [1]EDI!$L$2:$L$10000,"<>", [1]EDI!$R$2:$R$10000,">="&DATE(2026,1,1), [1]EDI!$I$2:$I$10000,"EDI" ) -> 57
A16: Reem Radwan | C16: =SUM(D16:G16) -> 23 | D16: =COUNTIFS([1]EDI!$S$2:$S$10000,"Reem Radwan", [1]EDI!$Q$2:$Q$10000, "In Progress", [1]EDI!$N$2:$N$10000,"DataSet Validation", [1]EDI!$L$2:$L$10000,"", [1]EDI!$I$2:$I$10000,"EDI") -> 1 | E16: =COUNTIFS([1]EDI!$S$2:$S$10000,"Reem Radwan", [1]EDI!$Q$2:$Q$10000, "In Progress", [1]EDI!$N$2:$N$10000,"Dataset Validation", [1]EDI!$L$2:$L$10000, "<>", [1]EDI!$I$2:$I$10000,"EDI") -> 0 | F16: =COUNTIFS([1]EDI!$S$2:$S$10000,"Reem Radwan", [1]EDI!$Q$2:$Q$10000, "In Progress", [1]EDI!$N$2:$N$10000,"Mapping", [1]EDI!$I$2:$I$10000,"EDI") -> 6 | G16: =COUNTIFS([1]EDI!$S$2:$S$10000,"Reem Radwan", [1]EDI!$Q$2:$Q$10000, "In Progress", [1]EDI!$N$2:$N$10000,"Testing", [1]EDI!$I$2:$I$10000,"EDI") -> 16 | H16: =COUNTIFS([1]EDI!$S$2:$S$10000,"Reem Radwan", [1]EDI!$Q$2:$Q$10000, "In Progress", [1]EDI!$N$2:$N$10000,"Ready For Production", [1]EDI!$I$2:$I$10000,"EDI") -> 0 | I16: =LARGE(Dates!Q4:Q50,1) -> 46215 | K16: =COUNTIFS([1]EDI!$S$2:$S$10000,"Reem Radwan", [1]EDI!$Q$2:$Q$10000, "In Progress", [1]EDI!$I$2:$I$10000,"Forms") -> 4 | L16: {=SUM(COUNTIFS([1]EDI!$S$2:$S$10000,"Reem Radwan", [1]EDI!$Q$2:$Q$10000,"In Progress", [1]EDI!$N$2:$N$10000,{"Mapping","Dataset Validation"}, [1]EDI!$I$2:$I$10000,"Forms"))} -> 1 | M16: =COUNTIFS([1]EDI!$S$2:$S$10000,"Reem Radwan", [1]EDI!$Q$2:$Q$10000, "In Progress", [1]EDI!$N$2:$N$10000,"Testing", [1]EDI!$I$2:$I$10000,"Forms") -> 1 | N16: =COUNTIFS([1]EDI!$S$2:$S$10000,"Reem Radwan", [1]EDI!$Q$2:$Q$10000, "In Progress", [1]EDI!$P$2:$P$10000,"Migration Testing", [1]EDI!$I$2:$I$10000,"Forms") -> 1 | O16: =COUNTIFS([1]EDI!$S$2:$S$10000,"Reem Radwan", [1]EDI!$Q$2:$Q$10000, "Live", [1]EDI!$P$2:$P$10000,"Production", [1]EDI!$I$2:$I$10000,"Forms") -> 4 | P16: =LARGE('Dates-Forms'!Q4:Q50,1) -> 46188 | Q16: =C16+K16 -> 27 | R16: =COUNTIFS( [1]EDI!$S$2:$S$10000,"Reem Radwan", [1]EDI!$L$2:$L$10000,"<>", [1]EDI!$R$2:$R$10000,">="&DATE(2025,1,1), [1]EDI!$R$2:$R$10000,"<"&DATE(2026,1,1), [1]EDI!$I$2:$I$10000,"EDI" ) -> 51 | S16: =COUNTIFS( [1]EDI!$S$2:$S$10000,"Reem Radwan", [1]EDI!$L$2:$L$10000,"<>", [1]EDI!$R$2:$R$10000,">="&DATE(2026,1,1), [1]EDI!$I$2:$I$10000,"EDI" ) -> 44
A17: Zeyad khaled | C17: =SUM(D17:G17) -> 22 | D17: =COUNTIFS([1]EDI!$S$2:$S$10000,"Zeyad khaled", [1]EDI!$Q$2:$Q$10000, "In Progress", [1]EDI!$N$2:$N$10000,"DataSet Validation", [1]EDI!$L$2:$L$10000,"", [1]EDI!$I$2:$I$10000,"EDI") -> 1 | E17: =COUNTIFS([1]EDI!$S$2:$S$10000,"Zeyad khaled", [1]EDI!$Q$2:$Q$10000, "In Progress", [1]EDI!$N$2:$N$10000,"Dataset Validation", [1]EDI!$L$2:$L$10000, "<>", [1]EDI!$I$2:$I$10000,"EDI") -> 0 | F17: =COUNTIFS([1]EDI!$S$2:$S$10000,"Zeyad khaled", [1]EDI!$Q$2:$Q$10000, "In Progress", [1]EDI!$N$2:$N$10000,"Mapping", [1]EDI!$I$2:$I$10000,"EDI") -> 4 | G17: =COUNTIFS([1]EDI!$S$2:$S$10000,"Zeyad khaled", [1]EDI!$Q$2:$Q$10000, "In Progress", [1]EDI!$N$2:$N$10000,"Testing", [1]EDI!$I$2:$I$10000,"EDI") -> 17 | H17: =COUNTIFS([1]EDI!$S$2:$S$10000,"Zeyad khaled", [1]EDI!$Q$2:$Q$10000, "In Progress", [1]EDI!$N$2:$N$10000,"Ready For Production", [1]EDI!$I$2:$I$10000,"EDI") -> 2 | I17: =LARGE(Dates!T4:T50,1) -> 46215 | K17: =COUNTIFS([1]EDI!$S$2:$S$10000,"Zeyad khaled", [1]EDI!$Q$2:$Q$10000, "In Progress", [1]EDI!$I$2:$I$10000,"Forms") -> 0 | L17: {=SUM(COUNTIFS([1]EDI!$S$2:$S$10000,"Zeyad khaled", [1]EDI!$Q$2:$Q$10000,"In Progress", [1]EDI!$N$2:$N$10000,{"Mapping","Dataset Validation"}, [1]EDI!$I$2:$I$10000,"Forms"))} -> 0 | M17: =COUNTIFS([1]EDI!$S$2:$S$10000,"Zeyad khaled", [1]EDI!$Q$2:$Q$10000, "In Progress", [1]EDI!$N$2:$N$10000,"Testing", [1]EDI!$I$2:$I$10000,"Forms") -> 0 | N17: =COUNTIFS([1]EDI!$S$2:$S$10000,"Zeyad khaled", [1]EDI!$Q$2:$Q$10000, "In Progress", [1]EDI!$P$2:$P$10000,"Migration Testing", [1]EDI!$I$2:$I$10000,"Forms") -> 0 | O17: =COUNTIFS([1]EDI!$S$2:$S$10000,"Zeyad khaled", [1]EDI!$Q$2:$Q$10000, "Live", [1]EDI!$P$2:$P$10000,"Production", [1]EDI!$I$2:$I$10000,"Forms") -> 0 | Q17: =C17+K17 -> 22 | R17: =COUNTIFS( [1]EDI!$S$2:$S$10000,"Zeyad khaled", [1]EDI!$L$2:$L$10000,"<>", [1]EDI!$R$2:$R$10000,">="&DATE(2025,1,1), [1]EDI!$R$2:$R$10000,"<"&DATE(2026,1,1), [1]EDI!$I$2:$I$10000,"EDI" ) -> 51 | S17: =COUNTIFS( [1]EDI!$S$2:$S$10000,"Zeyad khaled", [1]EDI!$L$2:$L$10000,"<>", [1]EDI!$R$2:$R$10000,">="&DATE(2026,1,1), [1]EDI!$I$2:$I$10000,"EDI" ) -> 48
A18: Giulie Alaa | C18: =SUM(D18:G18) -> 12 | D18: =COUNTIFS([1]EDI!$S$2:$S$10000,"Giulie Alaa", [1]EDI!$Q$2:$Q$10000, "In Progress", [1]EDI!$N$2:$N$10000,"DataSet Validation", [1]EDI!$L$2:$L$10000,"", [1]EDI!$I$2:$I$10000,"EDI") -> 0 | E18: =COUNTIFS([1]EDI!$S$2:$S$10000,"Giulie Alaa", [1]EDI!$Q$2:$Q$10000, "In Progress", [1]EDI!$N$2:$N$10000,"Dataset Validation", [1]EDI!$L$2:$L$10000, "<>", [1]EDI!$I$2:$I$10000,"EDI") -> 0 | F18: =COUNTIFS([1]EDI!$S$2:$S$10000,"Giulie Alaa", [1]EDI!$Q$2:$Q$10000, "In Progress", [1]EDI!$N$2:$N$10000,"Mapping", [1]EDI!$I$2:$I$10000,"EDI") -> 3 | G18: =COUNTIFS([1]EDI!$S$2:$S$10000,"Giulie Alaa", [1]EDI!$Q$2:$Q$10000, "In Progress", [1]EDI!$N$2:$N$10000,"Testing", [1]EDI!$I$2:$I$10000,"EDI") -> 9 | H18: =COUNTIFS([1]EDI!$S$2:$S$10000,"Giulie Alaa", [1]EDI!$Q$2:$Q$10000, "In Progress", [1]EDI!$N$2:$N$10000,"Ready For Production", [1]EDI!$I$2:$I$10000,"EDI") -> 0 | I18: =LARGE(Dates!AB4:AB50,1) -> 46215 | K18: =COUNTIFS([1]EDI!$S$2:$S$10000,"Giulie Alaa", [1]EDI!$Q$2:$Q$10000, "In Progress", [1]EDI!$I$2:$I$10000,"Forms") -> 0 | L18: {=SUM(COUNTIFS([1]EDI!$S$2:$S$10000,"Giulie Alaa", [1]EDI!$Q$2:$Q$10000,"In Progress", [1]EDI!$N$2:$N$10000,{"Mapping","Dataset Validation"}, [1]EDI!$I$2:$I$10000,"Forms"))} -> 0 | M18: =COUNTIFS([1]EDI!$S$2:$S$10000,"Giulie Alaa", [1]EDI!$Q$2:$Q$10000, "In Progress", [1]EDI!$N$2:$N$10000,"Testing", [1]EDI!$I$2:$I$10000,"Forms") -> 0 | N18: =COUNTIFS([1]EDI!$S$2:$S$10000,"Giulie Alaa", [1]EDI!$Q$2:$Q$10000, "In Progress", [1]EDI!$P$2:$P$10000,"Migration Testing", [1]EDI!$I$2:$I$10000,"Forms") -> 0 | O18: =COUNTIFS([1]EDI!$S$2:$S$10000,"Giulie Alaa", [1]EDI!$Q$2:$Q$10000, "Live", [1]EDI!$P$2:$P$10000,"Production", [1]EDI!$I$2:$I$10000,"Forms") -> 0 | Q18: =C18+K18 -> 12 | R18: =COUNTIFS( [1]EDI!$S$2:$S$10000,"Giulie Alaa", [1]EDI!$L$2:$L$10000,"<>", [1]EDI!$R$2:$R$10000,">="&DATE(2025,1,1), [1]EDI!$R$2:$R$10000,"<"&DATE(2026,1,1), [1]EDI!$I$2:$I$10000,"EDI" ) -> 0 | S18: =COUNTIFS( [1]EDI!$S$2:$S$10000,"Giulie Alaa", [1]EDI!$L$2:$L$10000,"<>", [1]EDI!$R$2:$R$10000,">="&DATE(2026,1,1), [1]EDI!$I$2:$I$10000,"EDI" ) -> 15
A19: Poula Moheb | C19: =SUM(D19:G19) -> 9 | D19: =COUNTIFS([1]EDI!$S$2:$S$10000,"Poula Moheb", [1]EDI!$Q$2:$Q$10000, "In Progress", [1]EDI!$N$2:$N$10000,"DataSet Validation", [1]EDI!$L$2:$L$10000,"", [1]EDI!$I$2:$I$10000,"EDI") -> 0 | E19: =COUNTIFS([1]EDI!$S$2:$S$10000,"Poula Moheb", [1]EDI!$Q$2:$Q$10000, "In Progress", [1]EDI!$N$2:$N$10000,"Dataset Validation", [1]EDI!$L$2:$L$10000, "<>", [1]EDI!$I$2:$I$10000,"EDI") -> 0 | F19: =COUNTIFS([1]EDI!$S$2:$S$10000,"Poula Moheb", [1]EDI!$Q$2:$Q$10000, "In Progress", [1]EDI!$N$2:$N$10000,"Mapping", [1]EDI!$I$2:$I$10000,"EDI") -> 1 | G19: =COUNTIFS([1]EDI!$S$2:$S$10000,"Poula Moheb", [1]EDI!$Q$2:$Q$10000, "In Progress", [1]EDI!$N$2:$N$10000,"Testing", [1]EDI!$I$2:$I$10000,"EDI") -> 8 | H19: =COUNTIFS([1]EDI!$S$2:$S$10000,"Poula Moheb", [1]EDI!$Q$2:$Q$10000, "In Progress", [1]EDI!$N$2:$N$10000,"Ready For Production", [1]EDI!$I$2:$I$10000,"EDI") -> 0 | I19: =LARGE(Dates!AC4:AC50,1) -> 46215 | K19: =COUNTIFS([1]EDI!$S$2:$S$10000,"Poula Moheb", [1]EDI!$Q$2:$Q$10000, "In Progress", [1]EDI!$I$2:$I$10000,"Forms") -> 0 | L19: {=SUM(COUNTIFS([1]EDI!$S$2:$S$10000,"Poula Moheb", [1]EDI!$Q$2:$Q$10000,"In Progress", [1]EDI!$N$2:$N$10000,{"Mapping","Dataset Validation"}, [1]EDI!$I$2:$I$10000,"Forms"))} -> 0 | M19: =COUNTIFS([1]EDI!$S$2:$S$10000,"Poula Moheb", [1]EDI!$Q$2:$Q$10000, "In Progress", [1]EDI!$N$2:$N$10000,"Testing", [1]EDI!$I$2:$I$10000,"Forms") -> 0 | N19: =COUNTIFS([1]EDI!$S$2:$S$10000,"Poula Moheb", [1]EDI!$Q$2:$Q$10000, "In Progress", [1]EDI!$P$2:$P$10000,"Migration Testing", [1]EDI!$I$2:$I$10000,"Forms") -> 0 | O19: =COUNTIFS([1]EDI!$S$2:$S$10000,"Poula Moheb", [1]EDI!$Q$2:$Q$10000, "Live", [1]EDI!$P$2:$P$10000,"Production", [1]EDI!$I$2:$I$10000,"Forms") -> 0 | Q19: =C19+K19 -> 9 | R19: =COUNTIFS( [1]EDI!$S$2:$S$10000,"Poula Moheb", [1]EDI!$L$2:$L$10000,"<>", [1]EDI!$R$2:$R$10000,">="&DATE(2025,1,1), [1]EDI!$R$2:$R$10000,"<"&DATE(2026,1,1), [1]EDI!$I$2:$I$10000,"EDI" ) -> 0 | S19: =COUNTIFS( [1]EDI!$S$2:$S$10000,"Poula Moheb", [1]EDI!$L$2:$L$10000,"<>", [1]EDI!$R$2:$R$10000,">="&DATE(2026,1,1), [1]EDI!$I$2:$I$10000,"EDI" ) -> 10
A20: Adham Akram | C20: =SUM(D20:G20) -> 10 | D20: =COUNTIFS([1]EDI!$S$2:$S$10000,"Adham Akram", [1]EDI!$Q$2:$Q$10000, "In Progress", [1]EDI!$N$2:$N$10000,"DataSet Validation", [1]EDI!$L$2:$L$10000,"", [1]EDI!$I$2:$I$10000,"EDI") -> 1 | E20: =COUNTIFS([1]EDI!$S$2:$S$10000,"Adham Akram", [1]EDI!$Q$2:$Q$10000, "In Progress", [1]EDI!$N$2:$N$10000,"Dataset Validation", [1]EDI!$L$2:$L$10000, "<>", [1]EDI!$I$2:$I$10000,"EDI") -> 0 | F20: =COUNTIFS([1]EDI!$S$2:$S$10000,"Adham Akram", [1]EDI!$Q$2:$Q$10000, "In Progress", [1]EDI!$N$2:$N$10000,"Mapping", [1]EDI!$I$2:$I$10000,"EDI") -> 5 | G20: =COUNTIFS([1]EDI!$S$2:$S$10000,"Adham Akram", [1]EDI!$Q$2:$Q$10000, "In Progress", [1]EDI!$N$2:$N$10000,"Testing", [1]EDI!$I$2:$I$10000,"EDI") -> 4 | H20: =COUNTIFS([1]EDI!$S$2:$S$10000,"Adham Akram", [1]EDI!$Q$2:$Q$10000, "In Progress", [1]EDI!$N$2:$N$10000,"Ready For Production", [1]EDI!$I$2:$I$10000,"EDI") -> 0 | I20: =LARGE(Dates!AD4:AD50,1) -> 46215 | K20: =COUNTIFS([1]EDI!$S$2:$S$10000,"Adham Akram", [1]EDI!$Q$2:$Q$10000, "In Progress", [1]EDI!$I$2:$I$10000,"Forms") -> 0 | L20: {=SUM(COUNTIFS([1]EDI!$S$2:$S$10000,"Adham Akram", [1]EDI!$Q$2:$Q$10000,"In Progress", [1]EDI!$N$2:$N$10000,{"Mapping","Dataset Validation"}, [1]EDI!$I$2:$I$10000,"Forms"))} -> 0 | M20: =COUNTIFS([1]EDI!$S$2:$S$10000,"Adham Akram", [1]EDI!$Q$2:$Q$10000, "In Progress", [1]EDI!$N$2:$N$10000,"Testing", [1]EDI!$I$2:$I$10000,"Forms") -> 0 | N20: =COUNTIFS([1]EDI!$S$2:$S$10000,"Adham Akram", [1]EDI!$Q$2:$Q$10000, "In Progress", [1]EDI!$P$2:$P$10000,"Migration Testing", [1]EDI!$I$2:$I$10000,"Forms") -> 0 | O20: =COUNTIFS([1]EDI!$S$2:$S$10000,"Adham Akram", [1]EDI!$Q$2:$Q$10000, "Live", [1]EDI!$P$2:$P$10000,"Production", [1]EDI!$I$2:$I$10000,"Forms") -> 0 | Q20: =C20+K20 -> 10 | R20: =COUNTIFS( [1]EDI!$S$2:$S$10000,"Adham Akram", [1]EDI!$L$2:$L$10000,"<>", [1]EDI!$R$2:$R$10000,">="&DATE(2025,1,1), [1]EDI!$R$2:$R$10000,"<"&DATE(2026,1,1), [1]EDI!$I$2:$I$10000,"EDI" ) -> 0 | S20: =COUNTIFS( [1]EDI!$S$2:$S$10000,"Adham Akram", [1]EDI!$L$2:$L$10000,"<>", [1]EDI!$R$2:$R$10000,">="&DATE(2026,1,1), [1]EDI!$I$2:$I$10000,"EDI" ) -> 9
A22: Totals | C22: =SUM(C3:C17) -> 251 | D22: =SUM(D3:D17) -> 5 | E22: =SUM(E3:E17) -> 2 | F22: =SUM(F3:F17) -> 63 | G22: =SUM(G3:G17) -> 181 | H22: =SUM(H3:H17) -> 10 | I22: =LARGE(I3:I17,1) -> #NUM! | K22: =SUM(K3:K17) -> 11 | L22: =SUM(L3:L17) -> 3 | M22: =SUM(M3:M17) -> 3 | N22: =SUM(N3:N17) -> 2 | O22: =SUM(O3:O17) -> 15 | P22: =LARGE(P3:P21,1) -> 46210 | Q22: =SUM(Q3:Q17) -> 262 | R22: =SUM(R3:R17) -> 683 | S22: =SUM(S3:S17) -> 531
A23: Current Total InProgress Queue | C23: =Q22+H22+B54+'RG CRs'!B8 -> 375 | D23: Child CRs InProgress | E23: {=SUMPRODUCT( (--([1]EDI!$S$2:$S$10000="Dina Medhat") * --([1]EDI!$Q$2:$Q$10000="In Progress") * --([1]EDI!$I$2:$I$10000="EDI") ) )} -> 21 | M23: =M22-N22 -> 1
A25: Month Input | C25: 45658 | D25: 45689 | E25: 45717 | F25: 45748 | G25: 45778 | H25: 45809 | I25: 45839 | K25: 45870 | L25: 45901 | M25: 45931 | N25: 45962 | O25: 45992 | P25: 46023 | Q25: 46054 | R25: 46082 | S25: 46113 | T25: 46143 | U25: 46174
A26: Total input | C26: {=SUMPRODUCT((MONTH([1]EDI!$R$2:$R$10000)=1)* (YEAR([1]EDI!$R$2:$R$10000)=2025))} -> 123 | D26: {=SUMPRODUCT((MONTH([1]EDI!$R$2:$R$10000)=2)* (YEAR([1]EDI!$R$2:$R$10000)=2025))} -> 102 | E26: {=SUMPRODUCT((MONTH([1]EDI!$R$2:$R$10000)=3)* (YEAR([1]EDI!$R$2:$R$10000)=2025))} -> 71 | F26: {=SUMPRODUCT((MONTH([1]EDI!$R$2:$R$10000)=4)* (YEAR([1]EDI!$R$2:$R$10000)=2025))} -> 82 | G26: {=SUMPRODUCT((MONTH([1]EDI!$R$2:$R$10000)=5)* (YEAR([1]EDI!$R$2:$R$10000)=2025))} -> 44 | H26: {=SUMPRODUCT((MONTH([1]EDI!$R$2:$R$10000)=6)* (YEAR([1]EDI!$R$2:$R$10000)=2025))} -> 64 | I26: {=SUMPRODUCT((MONTH([1]EDI!$R$2:$R$10000)=7)* (YEAR([1]EDI!$R$2:$R$10000)=2025))} -> 56 | J26: {=SUMPRODUCT((MONTH([1]EDI!$R$2:$R$10000)=1)* (YEAR([1]EDI!$R$2:$R$10000)=2025))} -> 123 | K26: {=SUMPRODUCT((MONTH([1]EDI!$R$2:$R$10000)=8)* (YEAR([1]EDI!$R$2:$R$10000)=2025))} -> 50 | L26: {=SUMPRODUCT((MONTH([1]EDI!$R$2:$R$10000)=9)* (YEAR([1]EDI!$R$2:$R$10000)=2025))} -> 77 | M26: {=SUMPRODUCT((MONTH([1]EDI!$R$2:$R$10000)=10)* (YEAR([1]EDI!$R$2:$R$10000)=2025))} -> 60 | N26: {=SUMPRODUCT((MONTH([1]EDI!$R$2:$R$10000)=11)* (YEAR([1]EDI!$R$2:$R$10000)=2025))} -> 98 | O26: {=SUMPRODUCT((MONTH([1]EDI!$R$2:$R$10000)=12)* (YEAR([1]EDI!$R$2:$R$10000)=2025))} -> 150 | P26: {=SUMPRODUCT((MONTH([1]EDI!$R$2:$R$10000)=1)* (YEAR([1]EDI!$R$2:$R$10000)=2026))} -> 165 | Q26: {=SUMPRODUCT((MONTH([1]EDI!$R$2:$R$10000)=2)* (YEAR([1]EDI!$R$2:$R$10000)=2026))} -> 124 | R26: {=SUMPRODUCT((MONTH([1]EDI!$R$2:$R$10000)=3)* (YEAR([1]EDI!$R$2:$R$10000)=2026))} -> 103 | S26: {=SUMPRODUCT((MONTH([1]EDI!$R$2:$R$10000)=4)* (YEAR([1]EDI!$R$2:$R$10000)=2026))} -> 136 | T26: {=SUMPRODUCT((MONTH([1]EDI!$R$2:$R$10000)=5)* (YEAR([1]EDI!$R$2:$R$10000)=2026))} -> 107 | U26: {=SUMPRODUCT((MONTH([1]EDI!$R$2:$R$10000)=6)* (YEAR([1]EDI!$R$2:$R$10000)=2026))} -> 135
A27: Not Started | C27: {=SUMPRODUCT( (--(INT([1]EDI!$R$2:$R$10000)>=DATE(2025,1,1))), (--(INT([1]EDI!$R$2:$R$10000)<=DATE(2025,1,31))), (--([1]EDI!$Q$2:$Q$10000="Not Started")))} -> 0 | D27: {=SUMPRODUCT( (--(INT([1]EDI!$R$2:$R$10000)>=DATE(2025,2,1))), (--(INT([1]EDI!$R$2:$R$10000)<=DATE(2025,2,29))), (--([1]EDI!$Q$2:$Q$10000="Not Started")))} -> 0 | E27: {=SUMPRODUCT( (--(INT([1]EDI!$R$2:$R$10000)>=DATE(2025,3,1))), (--(INT([1]EDI!$R$2:$R$10000)<=DATE(2025,3,31))), (--([1]EDI!$Q$2:$Q$10000="Not Started")))} -> 0 | F27: {=SUMPRODUCT( (--(INT([1]EDI!$R$2:$R$10000)>=DATE(2025,4,1))), (--(INT([1]EDI!$R$2:$R$10000)<=DATE(2025,4,30))), (--([1]EDI!$Q$2:$Q$10000="Not Started")))} -> 0 | G27: {=SUMPRODUCT( (--(INT([1]EDI!$R$2:$R$10000)>=DATE(2025,5,1))), (--(INT([1]EDI!$R$2:$R$10000)<=DATE(2025,5,31))), (--([1]EDI!$Q$2:$Q$10000="Not Started")))} -> 0 | H27: {=SUMPRODUCT( (--(INT([1]EDI!$R$2:$R$10000)>=DATE(2025,6,1))), (--(INT([1]EDI!$R$2:$R$10000)<=DATE(2025,6,30))), (--([1]EDI!$Q$2:$Q$10000="Not Started")))} -> 0 | I27: {=SUMPRODUCT( (--(INT([1]EDI!$R$2:$R$10000)>=DATE(2025,7,1))), (--(INT([1]EDI!$R$2:$R$10000)<=DATE(2025,7,31))), (--([1]EDI!$Q$2:$Q$10000="Not Started")))} -> 0 | J27: {=SUMPRODUCT( (--(INT([1]EDI!$R$2:$R$10000)>=DATE(2025,1,1))), (--(INT([1]EDI!$R$2:$R$10000)<=DATE(2025,1,31))), (--([1]EDI!$Q$2:$Q$10000="Not Started")))} -> 0 | K27: {=SUMPRODUCT( (--(INT([1]EDI!$R$2:$R$10000)>=DATE(2025,8,1))), (--(INT([1]EDI!$R$2:$R$10000)<=DATE(2025,8,31))), (--([1]EDI!$Q$2:$Q$10000="Not Started")))} -> 0 | L27: {=SUMPRODUCT( (--(INT([1]EDI!$R$2:$R$10000)>=DATE(2025,9,1))), (--(INT([1]EDI!$R$2:$R$10000)<=DATE(2025,9,30))), (--([1]EDI!$Q$2:$Q$10000="Not Started")))} -> 0 | M27: {=SUMPRODUCT( (--(INT([1]EDI!$R$2:$R$10000)>=DATE(2025,10,1))), (--(INT([1]EDI!$R$2:$R$10000)<=DATE(2025,10,31))), (--([1]EDI!$Q$2:$Q$10000="Not Started")))} -> 0 | N27: {=SUMPRODUCT( (--(INT([1]EDI!$R$2:$R$10000)>=DATE(2025,11,1))), (--(INT([1]EDI!$R$2:$R$10000)<=DATE(2025,11,30))), (--([1]EDI!$Q$2:$Q$10000="Not Started")))} -> 0 | O27: {=SUMPRODUCT( (--(INT([1]EDI!$R$2:$R$10000)>=DATE(2025,12,1))), (--(INT([1]EDI!$R$2:$R$10000)<=DATE(2025,12,31))), (--([1]EDI!$Q$2:$Q$10000="Not Started")))} -> 0 | P27: {=SUMPRODUCT( (--(INT([1]EDI!$R$2:$R$10000)>=DATE(2026,1,1))), (--(INT([1]EDI!$R$2:$R$10000)<=DATE(2026,1,31))), (--([1]EDI!$Q$2:$Q$10000="Not Started")))} -> 0 | Q27: {=SUMPRODUCT( (--(INT([1]EDI!$R$2:$R$10000)>=DATE(2026,2,1))), (--(INT([1]EDI!$R$2:$R$10000)<=DATE(2026,2,29))), (--([1]EDI!$Q$2:$Q$10000="Not Started")))} -> 0 | R27: {=SUMPRODUCT( (--(INT([1]EDI!$R$2:$R$10000)>=DATE(2026,3,1))), (--(INT([1]EDI!$R$2:$R$10000)<=DATE(2026,3,31))), (--([1]EDI!$Q$2:$Q$10000="Not Started")))} -> 0 | S27: {=SUMPRODUCT( (--(INT([1]EDI!$R$2:$R$10000)>=DATE(2026,4,1))), (--(INT([1]EDI!$R$2:$R$10000)<=DATE(2026,4,30))), (--([1]EDI!$Q$2:$Q$10000="Not Started")))} -> 0 | T27: {=SUMPRODUCT( (--(INT([1]EDI!$R$2:$R$10000)>=DATE(2026,5,1))), (--(INT([1]EDI!$R$2:$R$10000)<=DATE(2026,5,31))), (--([1]EDI!$Q$2:$Q$10000="Not Started")))} -> 0 | U27: {=SUMPRODUCT( (--(INT([1]EDI!$R$2:$R$10000)>=DATE(2026,6,1))), (--(INT([1]EDI!$R$2:$R$10000)<=DATE(2026,6,30))), (--([1]EDI!$Q$2:$Q$10000="Not Started")))} -> 1
A28: In Progress | C28: {=SUMPRODUCT( (--(INT([1]EDI!$R$2:$R$10000)>=DATE(2025,1,1))), (--(INT([1]EDI!$R$2:$R$10000)<=DATE(2025,1,31))), (--([1]EDI!$Q$2:$Q$10000="In Progress")))} -> 1 | D28: {=SUMPRODUCT( (--(INT([1]EDI!$R$2:$R$10000)>=DATE(2025,2,1))), (--(INT([1]EDI!$R$2:$R$10000)<=DATE(2025,2,29))), (--([1]EDI!$Q$2:$Q$10000="In Progress")))} -> 1 | E28: {=SUMPRODUCT( (--(INT([1]EDI!$R$2:$R$10000)>=DATE(2025,3,1))), (--(INT([1]EDI!$R$2:$R$10000)<=DATE(2025,3,31))), (--([1]EDI!$Q$2:$Q$10000="In Progress")))} -> 0 | F28: {=SUMPRODUCT( (--(INT([1]EDI!$R$2:$R$10000)>=DATE(2025,4,1))), (--(INT([1]EDI!$R$2:$R$10000)<=DATE(2025,4,30))), (--([1]EDI!$Q$2:$Q$10000="In Progress")))} -> 1 | G28: {=SUMPRODUCT( (--(INT([1]EDI!$R$2:$R$10000)>=DATE(2025,5,1))), (--(INT([1]EDI!$R$2:$R$10000)<=DATE(2025,5,30))), (--([1]EDI!$Q$2:$Q$10000="In Progress")))} -> 1 | H28: {=SUMPRODUCT( (--(INT([1]EDI!$R$2:$R$10000)>=DATE(2025,6,1))), (--(INT([1]EDI!$R$2:$R$10000)<=DATE(2025,6,30))), (--([1]EDI!$Q$2:$Q$10000="In Progress")))} -> 0 | I28: {=SUMPRODUCT( (--(INT([1]EDI!$R$2:$R$10000)>=DATE(2025,7,1))), (--(INT([1]EDI!$R$2:$R$10000)<=DATE(2025,7,31))), (--([1]EDI!$Q$2:$Q$10000="In Progress")))} -> 1 | J28: {=SUMPRODUCT( (--(INT([1]EDI!$R$2:$R$10000)>=DATE(2025,1,1))), (--(INT([1]EDI!$R$2:$R$10000)<=DATE(2025,1,31))), (--([1]EDI!$Q$2:$Q$10000="In Progress")))} -> 1 | K28: {=SUMPRODUCT( (--(INT([1]EDI!$R$2:$R$10000)>=DATE(2025,8,1))), (--(INT([1]EDI!$R$2:$R$10000)<=DATE(2025,8,31))), (--([1]EDI!$Q$2:$Q$10000="In Progress")))} -> 1 | L28: {=SUMPRODUCT( (--(INT([1]EDI!$R$2:$R$10000)>=DATE(2025,9,1))), (--(INT([1]EDI!$R$2:$R$10000)<=DATE(2025,9,30))), (--([1]EDI!$Q$2:$Q$10000="In Progress")))} -> 1 | M28: {=SUMPRODUCT( (--(INT([1]EDI!$R$2:$R$10000)>=DATE(2025,10,1))), (--(INT([1]EDI!$R$2:$R$10000)<=DATE(2025,10,31))), (--([1]EDI!$Q$2:$Q$10000="In Progress")))} -> 4 | N28: {=SUMPRODUCT( (--(INT([1]EDI!$R$2:$R$10000)>=DATE(2025,11,1))), (--(INT([1]EDI!$R$2:$R$10000)<=DATE(2025,11,30))), (--([1]EDI!$Q$2:$Q$10000="In Progress")))} -> 6 | O28: {=SUMPRODUCT( (--(INT([1]EDI!$R$2:$R$10000)>=DATE(2025,12,1))), (--(INT([1]EDI!$R$2:$R$10000)<=DATE(2025,12,31))), (--([1]EDI!$Q$2:$Q$10000="In Progress")))} -> 10 | P28: {=SUMPRODUCT( (--(INT([1]EDI!$R$2:$R$10000)>=DATE(2026,1,1))), (--(INT([1]EDI!$R$2:$R$10000)<=DATE(2026,1,31))), (--([1]EDI!$Q$2:$Q$10000="In Progress")))} -> 14 | Q28: {=SUMPRODUCT( (--(INT([1]EDI!$R$2:$R$10000)>=DATE(2026,2,1))), (--(INT([1]EDI!$R$2:$R$10000)<=DATE(2026,2,29))), (--([1]EDI!$Q$2:$Q$10000="In Progress")))} -> 25 | R28: {=SUMPRODUCT( (--(INT([1]EDI!$R$2:$R$10000)>=DATE(2026,3,1))), (--(INT([1]EDI!$R$2:$R$10000)<=DATE(2026,3,31))), (--([1]EDI!$Q$2:$Q$10000="In Progress")))} -> 31 | S28: {=SUMPRODUCT( (--(INT([1]EDI!$R$2:$R$10000)>=DATE(2026,4,1))), (--(INT([1]EDI!$R$2:$R$10000)<=DATE(2026,4,30))), (--([1]EDI!$Q$2:$Q$10000="In Progress")))} -> 80 | T28: {=SUMPRODUCT( (--(INT([1]EDI!$R$2:$R$10000)>=DATE(2026,5,1))), (--(INT([1]EDI!$R$2:$R$10000)<=DATE(2026,5,31))), (--([1]EDI!$Q$2:$Q$10000="In Progress")))} -> 83 | U28: {=SUMPRODUCT( (--(INT([1]EDI!$R$2:$R$10000)>=DATE(2026,6,1))), (--(INT([1]EDI!$R$2:$R$10000)<=DATE(2026,6,30))), (--([1]EDI!$Q$2:$Q$10000="In Progress")))} -> 114
A29: Production (Live) | C29: {=SUMPRODUCT( (--(INT([1]EDI!$R$2:$R$10000) >= DATE(2025,1,1))), (--(INT([1]EDI!$R$2:$R$10000) <= DATE(2025,1,31))), (--([1]EDI!$Q$2:$Q$10000 = "Live")) )} -> 87 | D29: {=SUMPRODUCT( (--(INT([1]EDI!$R$2:$R$10000) >= DATE(2025,2,1))), (--(INT([1]EDI!$R$2:$R$10000) <= DATE(2025,2,29))), (--([1]EDI!$Q$2:$Q$10000 = "Live")) )} -> 51 | E29: {=SUMPRODUCT( (--(INT([1]EDI!$R$2:$R$10000) >= DATE(2025,3,1))), (--(INT([1]EDI!$R$2:$R$10000) <= DATE(2025,3,31))), (--([1]EDI!$Q$2:$Q$10000 = "Live")) )} -> 48 | F29: {=SUMPRODUCT( (--(INT([1]EDI!$R$2:$R$10000) >= DATE(2025,4,1))), (--(INT([1]EDI!$R$2:$R$10000) <= DATE(2025,4,30))), (--([1]EDI!$Q$2:$Q$10000 = "Live")) )} -> 58 | G29: {=SUMPRODUCT( (--(INT([1]EDI!$R$2:$R$10000) >= DATE(2025,5,1))), (--(INT([1]EDI!$R$2:$R$10000) <= DATE(2025,5,31))), (--([1]EDI!$Q$2:$Q$10000 = "Live")) )} -> 25 | H29: {=SUMPRODUCT( (--(INT([1]EDI!$R$2:$R$10000) >= DATE(2025,6,1))), (--(INT([1]EDI!$R$2:$R$10000) <= DATE(2025,6,30))), (--([1]EDI!$Q$2:$Q$10000 = "Live")) )} -> 47 | I29: {=SUMPRODUCT( (--(INT([1]EDI!$R$2:$R$10000) >= DATE(2025,7,1))), (--(INT([1]EDI!$R$2:$R$10000) <= DATE(2025,7,31))), (--([1]EDI!$Q$2:$Q$10000 = "Live")) )} -> 42 | J29: {=SUMPRODUCT( (--(INT([1]EDI!$R$2:$R$10000) >= DATE(2025,1,1))), (--(INT([1]EDI!$R$2:$R$10000) <= DATE(2025,1,31))), (--([1]EDI!$Q$2:$Q$10000 = "Live")) )} -> 87 | K29: {=SUMPRODUCT( (--(INT([1]EDI!$R$2:$R$10000) >= DATE(2025,8,1))), (--(INT([1]EDI!$R$2:$R$10000) <= DATE(2025,8,31))), (--([1]EDI!$Q$2:$Q$10000 = "Live")) )} -> 37 | L29: {=SUMPRODUCT( (--(INT([1]EDI!$R$2:$R$10000) >= DATE(2025,9,1))), (--(INT([1]EDI!$R$2:$R$10000) <= DATE(2025,9,30))), (--([1]EDI!$Q$2:$Q$10000 = "Live")) )} -> 53 | M29: {=SUMPRODUCT( (--(INT([1]EDI!$R$2:$R$10000) >= DATE(2025,10,1))), (--(INT([1]EDI!$R$2:$R$10000) <= DATE(2025,10,31))), (--([1]EDI!$Q$2:$Q$10000 = "Live")) )} -> 50 | N29: {=SUMPRODUCT( (--(INT([1]EDI!$R$2:$R$10000) >= DATE(2025,11,1))), (--(INT([1]EDI!$R$2:$R$10000) <= DATE(2025,11,30))), (--([1]EDI!$Q$2:$Q$10000 = "Live")) )} -> 78 | O29: {=SUMPRODUCT( (--(INT([1]EDI!$R$2:$R$10000) >= DATE(2025,12,1))), (--(INT([1]EDI!$R$2:$R$10000) <= DATE(2025,12,31))), (--([1]EDI!$Q$2:$Q$10000 = "Live")) )} -> 118 | P29: {=SUMPRODUCT( (--(INT([1]EDI!$R$2:$R$10000) >= DATE(2026,1,1))), (--(INT([1]EDI!$R$2:$R$10000) <= DATE(2026,1,31))), (--([1]EDI!$Q$2:$Q$10000 = "Live")) )} -> 119 | Q29: {=SUMPRODUCT( (--(INT([1]EDI!$R$2:$R$10000) >= DATE(2026,2,1))), (--(INT([1]EDI!$R$2:$R$10000) <= DATE(2026,2,29))), (--([1]EDI!$Q$2:$Q$10000 = "Live")) )} -> 91 | R29: {=SUMPRODUCT( (--(INT([1]EDI!$R$2:$R$10000) >= DATE(2026,3,1))), (--(INT([1]EDI!$R$2:$R$10000) <= DATE(2026,3,31))), (--([1]EDI!$Q$2:$Q$10000 = "Live")) )} -> 63 | S29: {=SUMPRODUCT( (--(INT([1]EDI!$R$2:$R$10000) >= DATE(2026,4,1))), (--(INT([1]EDI!$R$2:$R$10000) <= DATE(2026,4,30))), (--([1]EDI!$Q$2:$Q$10000 = "Live")) )} -> 48 | T29: {=SUMPRODUCT( (--(INT([1]EDI!$R$2:$R$10000) >= DATE(2026,5,1))), (--(INT([1]EDI!$R$2:$R$10000) <= DATE(2026,5,31))), (--([1]EDI!$Q$2:$Q$10000 = "Live")) )} -> 15 | U29: {=SUMPRODUCT( (--(INT([1]EDI!$R$2:$R$10000) >= DATE(2026,6,1))), (--(INT([1]EDI!$R$2:$R$10000) <= DATE(2026,6,30))), (--([1]EDI!$Q$2:$Q$10000 = "Live")) )} -> 8
A30: Cancelled | C30: {=SUMPRODUCT( (--(INT([1]EDI!$R$2:$R$10000)>=DATE(2025,1,1))), (--(INT([1]EDI!$R$2:$R$10000)<=DATE(2025,1,31))), (--([1]EDI!$Q$2:$Q$10000="Cancelled")))} -> 35 | D30: {=SUMPRODUCT( (--(INT([1]EDI!$R$2:$R$10000)>=DATE(2025,2,1))), (--(INT([1]EDI!$R$2:$R$10000)<=DATE(2025,2,29))), (--([1]EDI!$Q$2:$Q$10000="Cancelled")))} -> 50 | E30: {=SUMPRODUCT( (--(INT([1]EDI!$R$2:$R$10000)>=DATE(2025,3,1))), (--(INT([1]EDI!$R$2:$R$10000)<=DATE(2025,3,31))), (--([1]EDI!$Q$2:$Q$10000="Cancelled")))} -> 23 | F30: {=SUMPRODUCT( (--(INT([1]EDI!$R$2:$R$10000)>=DATE(2025,4,1))), (--(INT([1]EDI!$R$2:$R$10000)<=DATE(2025,4,30))), (--([1]EDI!$Q$2:$Q$10000="Cancelled")))} -> 22 | G30: {=SUMPRODUCT( (--(INT([1]EDI!$R$2:$R$10000)>=DATE(2025,5,1))), (--(INT([1]EDI!$R$2:$R$10000)<=DATE(2025,5,31))), (--([1]EDI!$Q$2:$Q$10000="Cancelled")))} -> 18 | H30: {=SUMPRODUCT( (--(INT([1]EDI!$R$2:$R$10000)>=DATE(2025,6,1))), (--(INT([1]EDI!$R$2:$R$10000)<=DATE(2025,6,30))), (--([1]EDI!$Q$2:$Q$10000="Cancelled")))} -> 17 | I30: {=SUMPRODUCT( (--(INT([1]EDI!$R$2:$R$10000)>=DATE(2025,7,1))), (--(INT([1]EDI!$R$2:$R$10000)<=DATE(2025,7,31))), (--([1]EDI!$Q$2:$Q$10000="Cancelled")))} -> 13 | J30: {=SUMPRODUCT( (--(INT([1]EDI!$R$2:$R$10000)>=DATE(2025,1,1))), (--(INT([1]EDI!$R$2:$R$10000)<=DATE(2025,1,31))), (--([1]EDI!$Q$2:$Q$10000="Cancelled")))} -> 35 | K30: {=SUMPRODUCT( (--(INT([1]EDI!$R$2:$R$10000)>=DATE(2025,8,1))), (--(INT([1]EDI!$R$2:$R$10000)<=DATE(2025,8,31))), (--([1]EDI!$Q$2:$Q$10000="Cancelled")))} -> 12 | L30: {=SUMPRODUCT( (--(INT([1]EDI!$R$2:$R$10000)>=DATE(2025,9,1))), (--(INT([1]EDI!$R$2:$R$10000)<=DATE(2025,9,30))), (--([1]EDI!$Q$2:$Q$10000="Cancelled")))} -> 23 | M30: {=SUMPRODUCT( (--(INT([1]EDI!$R$2:$R$10000)>=DATE(2025,10,1))), (--(INT([1]EDI!$R$2:$R$10000)<=DATE(2025,10,31))), (--([1]EDI!$Q$2:$Q$10000="Cancelled")))} -> 6 | N30: {=SUMPRODUCT( (--(INT([1]EDI!$R$2:$R$10000)>=DATE(2025,11,1))), (--(INT([1]EDI!$R$2:$R$10000)<=DATE(2025,11,30))), (--([1]EDI!$Q$2:$Q$10000="Cancelled")))} -> 14 | O30: {=SUMPRODUCT( (--(INT([1]EDI!$R$2:$R$10000)>=DATE(2025,12,1))), (--(INT([1]EDI!$R$2:$R$10000)<=DATE(2025,12,31))), (--([1]EDI!$Q$2:$Q$10000="Cancelled")))} -> 22 | P30: {=SUMPRODUCT( (--(INT([1]EDI!$R$2:$R$10000)>=DATE(2026,1,1))), (--(INT([1]EDI!$R$2:$R$10000)<=DATE(2026,1,31))), (--([1]EDI!$Q$2:$Q$10000="Cancelled")))} -> 31 | Q30: {=SUMPRODUCT( (--(INT([1]EDI!$R$2:$R$10000)>=DATE(2026,2,1))), (--(INT([1]EDI!$R$2:$R$10000)<=DATE(2026,2,29))), (--([1]EDI!$Q$2:$Q$10000="Cancelled")))} -> 8 | R30: {=SUMPRODUCT( (--(INT([1]EDI!$R$2:$R$10000)>=DATE(2026,3,1))), (--(INT([1]EDI!$R$2:$R$10000)<=DATE(2026,3,31))), (--([1]EDI!$Q$2:$Q$10000="Cancelled")))} -> 9 | S30: {=SUMPRODUCT( (--(INT([1]EDI!$R$2:$R$10000)>=DATE(2026,4,1))), (--(INT([1]EDI!$R$2:$R$10000)<=DATE(2026,4,30))), (--([1]EDI!$Q$2:$Q$10000="Cancelled")))} -> 8 | T30: {=SUMPRODUCT( (--(INT([1]EDI!$R$2:$R$10000)>=DATE(2026,5,1))), (--(INT([1]EDI!$R$2:$R$10000)<=DATE(2026,5,31))), (--([1]EDI!$Q$2:$Q$10000="Cancelled")))} -> 9 | U30: {=SUMPRODUCT( (--(INT([1]EDI!$R$2:$R$10000)>=DATE(2026,6,1))), (--(INT([1]EDI!$R$2:$R$10000)<=DATE(2026,6,30))), (--([1]EDI!$Q$2:$Q$10000="Cancelled")))} -> 12
A31: On Hold | C31: {=SUMPRODUCT( (--(INT([1]EDI!$R$2:$R$10000)>=DATE(2025,1,1))), (--(INT([1]EDI!$R$2:$R$10000)<=DATE(2025,1,31))), (--([1]EDI!$Q$2:$Q$10000="On Hold")))} -> 0 | D31: {=SUMPRODUCT( (--(INT([1]EDI!$R$2:$R$10000)>=DATE(2025,2,1))), (--(INT([1]EDI!$R$2:$R$10000)<=DATE(2025,2,29))), (--([1]EDI!$Q$2:$Q$10000="On Hold")))} -> 0 | E31: {=SUMPRODUCT( (--(INT([1]EDI!$R$2:$R$10000)>=DATE(2025,3,1))), (--(INT([1]EDI!$R$2:$R$10000)<=DATE(2025,3,31))), (--([1]EDI!$Q$2:$Q$10000="On Hold")))} -> 0 | F31: {=SUMPRODUCT( (--(INT([1]EDI!$R$2:$R$10000)>=DATE(2025,4,1))), (--(INT([1]EDI!$R$2:$R$10000)<=DATE(2025,4,30))), (--([1]EDI!$Q$2:$Q$10000="On Hold")))} -> 1 | G31: {=SUMPRODUCT( (--(INT([1]EDI!$R$2:$R$10000)>=DATE(2025,5,1))), (--(INT([1]EDI!$R$2:$R$10000)<=DATE(2025,5,31))), (--([1]EDI!$Q$2:$Q$10000="On Hold")))} -> 0 | H31: {=SUMPRODUCT( (--(INT([1]EDI!$R$2:$R$10000)>=DATE(2025,6,1))), (--(INT([1]EDI!$R$2:$R$10000)<=DATE(2025,6,30))), (--([1]EDI!$Q$2:$Q$10000="On Hold")))} -> 0 | I31: {=SUMPRODUCT( (--(INT([1]EDI!$R$2:$R$10000)>=DATE(2025,7,1))), (--(INT([1]EDI!$R$2:$R$10000)<=DATE(2025,7,31))), (--([1]EDI!$Q$2:$Q$10000="On Hold")))} -> 0 | J31: {=SUMPRODUCT( (--(INT([1]EDI!$R$2:$R$10000)>=DATE(2025,1,1))), (--(INT([1]EDI!$R$2:$R$10000)<=DATE(2025,1,31))), (--([1]EDI!$Q$2:$Q$10000="On Hold")))} -> 0 | K31: {=SUMPRODUCT( (--(INT([1]EDI!$R$2:$R$10000)>=DATE(2025,8,1))), (--(INT([1]EDI!$R$2:$R$10000)<=DATE(2025,8,31))), (--([1]EDI!$Q$2:$Q$10000="On Hold")))} -> 0 | L31: {=SUMPRODUCT( (--(INT([1]EDI!$R$2:$R$10000)>=DATE(2025,9,1))), (--(INT([1]EDI!$R$2:$R$10000)<=DATE(2025,9,30))), (--([1]EDI!$Q$2:$Q$10000="On Hold")))} -> 0 | M31: {=SUMPRODUCT( (--(INT([1]EDI!$R$2:$R$10000)>=DATE(2025,10,1))), (--(INT([1]EDI!$R$2:$R$10000)<=DATE(2025,10,31))), (--([1]EDI!$Q$2:$Q$10000="On Hold")))} -> 0 | N31: {=SUMPRODUCT( (--(INT([1]EDI!$R$2:$R$10000)>=DATE(2025,11,1))), (--(INT([1]EDI!$R$2:$R$10000)<=DATE(2025,11,30))), (--([1]EDI!$Q$2:$Q$10000="On Hold")))} -> 0 | O31: {=SUMPRODUCT( (--(INT([1]EDI!$R$2:$R$10000)>=DATE(2025,12,1))), (--(INT([1]EDI!$R$2:$R$10000)<=DATE(2025,12,31))), (--([1]EDI!$Q$2:$Q$10000="On Hold")))} -> 0 | P31: {=SUMPRODUCT( (--(INT([1]EDI!$R$2:$R$10000)>=DATE(2026,1,1))), (--(INT([1]EDI!$R$2:$R$10000)<=DATE(2026,1,31))), (--([1]EDI!$Q$2:$Q$10000="On Hold")))} -> 1 | Q31: {=SUMPRODUCT( (--(INT([1]EDI!$R$2:$R$10000)>=DATE(2026,2,1))), (--(INT([1]EDI!$R$2:$R$10000)<=DATE(2026,2,29))), (--([1]EDI!$Q$2:$Q$10000="On Hold")))} -> 0 | R31: {=SUMPRODUCT( (--(INT([1]EDI!$R$2:$R$10000)>=DATE(2026,3,1))), (--(INT([1]EDI!$R$2:$R$10000)<=DATE(2026,3,31))), (--([1]EDI!$Q$2:$Q$10000="On Hold")))} -> 0 | S31: {=SUMPRODUCT( (--(INT([1]EDI!$R$2:$R$10000)>=DATE(2026,4,1))), (--(INT([1]EDI!$R$2:$R$10000)<=DATE(2026,4,30))), (--([1]EDI!$Q$2:$Q$10000="On Hold")))} -> 0 | T31: {=SUMPRODUCT( (--(INT([1]EDI!$R$2:$R$10000)>=DATE(2026,5,1))), (--(INT([1]EDI!$R$2:$R$10000)<=DATE(2026,5,31))), (--([1]EDI!$Q$2:$Q$10000="On Hold")))} -> 0 | U31: {=SUMPRODUCT( (--(INT([1]EDI!$R$2:$R$10000)>=DATE(2026,6,1))), (--(INT([1]EDI!$R$2:$R$10000)<=DATE(2026,6,30))), (--([1]EDI!$Q$2:$Q$10000="On Hold")))} -> 0
